Workbook
Name SLC6A1: 'Imported Data'!$M$3:$M$1000
Name ZC4H2: 'Imported Data'!$G$3:$G$1000
Name Combined: 'Imported Data'!$S$3:$S$1000
Name MAPK8IP3: 'Imported Data'!$A$3:$A$1000

Sheet Gene URLs
A1: URL | B1: Gene
A2: https://docs.google.com/spreadsheets/d/1Spt8qYim4XPspej6XI67k_I63yauq9zr2pJnMcsXZSA/edit | B2: MAPK8IP3
A3: https://docs.google.com/spreadsheets/d/1RqToPiEtpgdNCmgHZvuiPqup_bsjIR1hzf4EP3GpPbg/edit | B3: ZC4H2
A4: https://docs.google.com/spreadsheets/d/1GhCK3NOBh3-48G6vkiPgGToNn9NYo1GQ7HDRjJAP89g/edit | B4: SLC6A1

Sheet Imported Data
A1: MAPK8IP3 | B1: {=INDEX('Gene URLs'!A2:A1000, MATCH(A1, 'Gene URLs'!B2:B1000, 0))} -> https://docs.google.com/spreadsheets/d/1Spt8qYim4XPspej6XI67k_I63yauq9zr2pJnMcsXZSA/edit | G1: ZC4H2 | H1: {=INDEX('Gene URLs'!A2:A1000, MATCH(G1, 'Gene URLs'!B2:B1000, 0))} -> https://docs.google.com/spreadsheets/d/1RqToPiEtpgdNCmgHZvuiPqup_bsjIR1hzf4EP3GpPbg/edit | M1: SLC6A1 | N1: {=INDEX('Gene URLs'!A2:A1000, MATCH(M1, 'Gene URLs'!B2:B1000, 0))} -> https://docs.google.com/spreadsheets/d/1GhCK3NOBh3-48G6vkiPgGToNn9NYo1GQ7HDRjJAP89g/edit | S1: Combined
A2: =IFERROR(__xludf.DUMMYFUNCTION("IMPORTRANGE(B1, ""Final Clinician Ranking!A:C"")"),"DrugBank:Main Name") -> DrugBank:Main Name | B2: =IFERROR(__xludf.DUMMYFUNCTION("""COMPUTED_VALUE"""),"Score") -> Score | C2: =IFERROR(__xludf.DUMMYFUNCTION("""COMPUTED_VALUE"""),"Pre-clinician Score") -> Pre-clinician Score | D2: =IFERROR(__xludf.DUMMYFUNCTION("IMPORTRANGE(B1, ""Final Clinician Ranking!L:M"")"),"Have It") -> Have It | E2: =IFERROR(__xludf.DUMMYFUNCTION("""COMPUTED_VALUE"""),"Screened It") -> Screened It | G2: =IFERROR(__xludf.DUMMYFUNCTION("IMPORTRANGE(H1, ""Final Clinician Ranking!A:C"")"),"DrugBank:Main Name") -> DrugBank:Main Name | H2: =IFERROR(__xludf.DUMMYFUNCTION("""COMPUTED_VALUE"""),"Score") -> Score | I2: =IFERROR(__xludf.DUMMYFUNCTION("""COMPUTED_VALUE"""),"Pre-clinician score") -> Pre-clinician score | J2: =IFERROR(__xludf.DUMMYFUNCTION("IMPORTRANGE(H1, ""Final Clinician Ranking!K:L"")"),"Have It") -> Have It | K2: =IFERROR(__xludf.DUMMYFUNCTION("""COMPUTED_VALUE"""),"Screened It") -> Screened It | M2: =IFERROR(__xludf.DUMMYFUNCTION("IMPORTRANGE(N1, ""Final Clinician Ranking!A:C"")"),"DrugBank:Main Name") -> DrugBank:Main Name | N2: =IFERROR(__xludf.DUMMYFUNCTION("""COMPUTED_VALUE"""),"Score") -> Score | O2: =IFERROR(__xludf.DUMMYFUNCTION("""COMPUTED_VALUE"""),"Pre-clinician score") -> Pre-clinician score | P2: =IFERROR(__xludf.DUMMYFUNCTION("IMPORTRANGE(N1, ""Final Clinician Ranking!L:M"")"),"Have It") -> Have It | Q2: =IFERROR(__xludf.DUMMYFUNCTION("""COMPUTED_VALUE"""),"Screened It") -> Screened It | S2: DrugBank:Main Name | T2: Score | U2: Pre-clinician score | V2: Have It
A3: =IFERROR(__xludf.DUMMYFUNCTION("""COMPUTED_VALUE"""),"Acetaminophen") -> Acetaminophen | B3: =IFERROR(__xludf.DUMMYFUNCTION("""COMPUTED_VALUE"""),6.0) -> 6 | C3: =IFERROR(__xludf.DUMMYFUNCTION("""COMPUTED_VALUE"""),3.0) -> 3 | D3: =IFERROR(__xludf.DUMMYFUNCTION("""COMPUTED_VALUE"""),FALSE) -> FALSE | E3: =IFERROR(__xludf.DUMMYFUNCTION("""COMPUTED_VALUE"""),TRUE) -> TRUE | G3: =IFERROR(__xludf.DUMMYFUNCTION("""COMPUTED_VALUE"""),"Acetaminophen") -> Acetaminophen | H3: =IFERROR(__xludf.DUMMYFUNCTION("""COMPUTED_VALUE"""),6.0) -> 6 | I3: =IFERROR(__xludf.DUMMYFUNCTION("""COMPUTED_VALUE"""),3.0) -> 3 | J3: =IFERROR(__xludf.DUMMYFUNCTION("""COMPUTED_VALUE"""),FALSE) -> FALSE | K3: =IFERROR(__xludf.DUMMYFUNCTION("""COMPUTED_VALUE"""),FALSE) -> FALSE | M3: =IFERROR(__xludf.DUMMYFUNCTION("""COMPUTED_VALUE"""),"Acamprosate") -> Acamprosate | N3: =IFERROR(__xludf.DUMMYFUNCTION("""COMPUTED_VALUE"""),1.0) -> 1 | O3: =IFERROR(__xludf.DUMMYFUNCTION("""COMPUTED_VALUE"""),3.0) -> 3 | P3: =IFERROR(__xludf.DUMMYFUNCTION("""COMPUTED_VALUE"""),FALSE) -> FALSE | Q3: =IFERROR(__xludf.DUMMYFUNCTION("""COMPUTED_VALUE"""),FALSE) -> FALSE | S3: {=SORT(UNIQUE({MAPK8IP3; ZC4H2; SLC6A1}))} -> Acamprosate | T3: {=XLOOKUP(S3, MAPK8IP3, B3:B1000, XLOOKUP(S3, ZC4H2, H3:H1000, XLOOKUP(S3, SLC6A1, N3:N1000)))} -> 1 | U3: {=XLOOKUP(S3, MAPK8IP3, C3:C1000, XLOOKUP(S3, ZC4H2, I3:I1000, XLOOKUP(S3, SLC6A1, O3:O1000)))} -> 3 | V3: {=XLOOKUP(S3, MAPK8IP3, D3:D1000, XLOOKUP(S3, ZC4H2, J3:J1000, XLOOKUP(S3, SLC6A1, P3:P1000)))} -> FALSE
A4: =IFERROR(__xludf.DUMMYFUNCTION("""COMPUTED_VALUE"""),"Acetylcysteine") -> Acetylcysteine | B4: =IFERROR(__xludf.DUMMYFUNCTION("""COMPUTED_VALUE"""),6.0) -> 6 | C4: =IFERROR(__xludf.DUMMYFUNCTION("""COMPUTED_VALUE"""),3.0) -> 3 | D4: =IFERROR(__xludf.DUMMYFUNCTION("""COMPUTED_VALUE"""),TRUE) -> TRUE | E4: =IFERROR(__xludf.DUMMYFUNCTION("""COMPUTED_VALUE"""),TRUE) -> TRUE | G4: =IFERROR(__xludf.DUMMYFUNCTION("""COMPUTED_VALUE"""),"Acetylcysteine") -> Acetylcysteine | H4: =IFERROR(__xludf.DUMMYFUNCTION("""COMPUTED_VALUE"""),6.0) -> 6 | I4: =IFERROR(__xludf.DUMMYFUNCTION("""COMPUTED_VALUE"""),3.0) -> 3 | J4: =IFERROR(__xludf.DUMMYFUNCTION("""COMPUTED_VALUE"""),TRUE) -> TRUE | K4: =IFERROR(__xludf.DUMMYFUNCTION("""COMPUTED_VALUE"""),FALSE) -> FALSE | M4: =IFERROR(__xludf.DUMMYFUNCTION("""COMPUTED_VALUE"""),"Acetaminophen") -> Acetaminophen | N4: =IFERROR(__xludf.DUMMYFUNCTION("""COMPUTED_VALUE"""),6.0) -> 6 | O4: =IFERROR(__xludf.DUMMYFUNCTION("""COMPUTED_VALUE"""),3.0) -> 3 | P4: =IFERROR(__xludf.DUMMYFUNCTION("""COMPUTED_VALUE"""),FALSE) -> FALSE | Q4: =IFERROR(__xludf.DUMMYFUNCTION("""COMPUTED_VALUE"""),FALSE) -> FALSE | S4: Acetaminophen | T4: {=XLOOKUP(S4, MAPK8IP3, B3:B1000, XLOOKUP(S4, ZC4H2, H3:H1000, XLOOKUP(S4, SLC6A1, N3:N1000)))} -> 6 | U4: {=XLOOKUP(S4, MAPK8IP3, C3:C1000, XLOOKUP(S4, ZC4H2, I3:I1000, XLOOKUP(S4, SLC6A1, O3:O1000)))} -> 3 | V4: {=XLOOKUP(S4, MAPK8IP3, D3:D1000, XLOOKUP(S4, ZC4H2, J3:J1000, XLOOKUP(S4, SLC6A1, P3:P1000)))} -> FALSE
A5: =IFERROR(__xludf.DUMMYFUNCTION("""COMPUTED_VALUE"""),"Amitriptyline") -> Amitriptyline | B5: =IFERROR(__xludf.DUMMYFUNCTION("""COMPUTED_VALUE"""),6.0) -> 6 | C5: =IFERROR(__xludf.DUMMYFUNCTION("""COMPUTED_VALUE"""),3.0) -> 3 | D5: =IFERROR(__xludf.DUMMYFUNCTION("""COMPUTED_VALUE"""),FALSE) -> FALSE | E5: =IFERROR(__xludf.DUMMYFUNCTION("""COMPUTED_VALUE"""),FALSE) -> FALSE | G5: =IFERROR(__xludf.DUMMYFUNCTION("""COMPUTED_VALUE"""),"Amitriptyline") -> Amitriptyline | H5: =IFERROR(__xludf.DUMMYFUNCTION("""COMPUTED_VALUE"""),6.0) -> 6 | I5: =IFERROR(__xludf.DUMMYFUNCTION("""COMPUTED_VALUE"""),3.0) -> 3 | J5: =IFERROR(__xludf.DUMMYFUNCTION("""COMPUTED_VALUE"""),FALSE) -> FALSE | K5: =IFERROR(__xludf.DUMMYFUNCTION("""COMPUTED_VALUE"""),FALSE) -> FALSE | M5: =IFERROR(__xludf.DUMMYFUNCTION("""COMPUTED_VALUE"""),"Acetylcysteine") -> Acetylcysteine | N5: =IFERROR(__xludf.DUMMYFUNCTION("""COMPUTED_VALUE"""),6.0) -> 6 | O5: =IFERROR(__xludf.DUMMYFUNCTION("""COMPUTED_VALUE"""),3.0) -> 3 | P5: =IFERROR(__xludf.DUMMYFUNCTION("""COMPUTED_VALUE"""),TRUE) -> TRUE | Q5: =IFERROR(__xludf.DUMMYFUNCTION("""COMPUTED_VALUE"""),FALSE) -> FALSE | S5: Acetylcysteine | T5: {=XLOOKUP(S5, MAPK8IP3, B3:B1000, XLOOKUP(S5, ZC4H2, H3:H1000, XLOOKUP(S5, SLC6A1, N3:N1000)))} -> 6 | U5: {=XLOOKUP(S5, MAPK8IP3, C3:C1000, XLOOKUP(S5, ZC4H2, I3:I1000, XLOOKUP(S5, SLC6A1, O3:O1000)))} -> 3 | V5: {=XLOOKUP(S5, MAPK8IP3, D3:D1000, XLOOKUP(S5, ZC4H2, J3:J1000, XLOOKUP(S5, SLC6A1, P3:P1000)))} -> TRUE
A6: =IFERROR(__xludf.DUMMYFUNCTION("""COMPUTED_VALUE"""),"Azelaic acid") -> Azelaic acid | B6: =IFERROR(__xludf.DUMMYFUNCTION("""COMPUTED_VALUE"""),6.0) -> 6 | C6: =IFERROR(__xludf.DUMMYFUNCTION("""COMPUTED_VALUE"""),3.0) -> 3 | D6: =IFERROR(__xludf.DUMMYFUNCTION("""COMPUTED_VALUE"""),FALSE) -> FALSE | E6: =IFERROR(__xludf.DUMMYFUNCTION("""COMPUTED_VALUE"""),FALSE) -> FALSE | G6: =IFERROR(__xludf.DUMMYFUNCTION("""COMPUTED_VALUE"""),"Betamethasone") -> Betamethasone | H6: =IFERROR(__xludf.DUMMYFUNCTION("""COMPUTED_VALUE"""),6.0) -> 6 | I6: =IFERROR(__xludf.DUMMYFUNCTION("""COMPUTED_VALUE"""),3.0) -> 3 | J6: =IFERROR(__xludf.DUMMYFUNCTION("""COMPUTED_VALUE"""),FALSE) -> FALSE | K6: =IFERROR(__xludf.DUMMYFUNCTION("""COMPUTED_VALUE"""),FALSE) -> FALSE | M6: =IFERROR(__xludf.DUMMYFUNCTION("""COMPUTED_VALUE"""),"Amantadine") -> Amantadine | N6: =IFERROR(__xludf.DUMMYFUNCTION("""COMPUTED_VALUE"""),2.0) -> 2 | O6: =IFERROR(__xludf.DUMMYFUNCTION("""COMPUTED_VALUE"""),3.0) -> 3 | P6: =IFERROR(__xludf.DUMMYFUNCTION("""COMPUTED_VALUE"""),TRUE) -> TRUE | Q6: =IFERROR(__xludf.DUMMYFUNCTION("""COMPUTED_VALUE"""),FALSE) -> FALSE | S6: Alfacalcidol | T6: {=XLOOKUP(S6, MAPK8IP3, B3:B1000, XLOOKUP(S6, ZC4H2, H3:H1000, XLOOKUP(S6, SLC6A1, N3:N1000)))} -> 3 | U6: {=XLOOKUP(S6, MAPK8IP3, C3:C1000, XLOOKUP(S6, ZC4H2, I3:I1000, XLOOKUP(S6, SLC6A1, O3:O1000)))} -> 3 | V6: {=XLOOKUP(S6, MAPK8IP3, D3:D1000, XLOOKUP(S6, ZC4H2, J3:J1000, XLOOKUP(S6, SLC6A1, P3:P1000)))} -> FALSE
A7: =IFERROR(__xludf.DUMMYFUNCTION("""COMPUTED_VALUE"""),"Betamethasone") -> Betamethasone | B7: =IFERROR(__xludf.DUMMYFUNCTION("""COMPUTED_VALUE"""),6.0) -> 6 | C7: =IFERROR(__xludf.DUMMYFUNCTION("""COMPUTED_VALUE"""),3.0) -> 3 | D7: =IFERROR(__xludf.DUMMYFUNCTION("""COMPUTED_VALUE"""),FALSE) -> FALSE | E7: =IFERROR(__xludf.DUMMYFUNCTION("""COMPUTED_VALUE"""),FALSE) -> FALSE | G7: =IFERROR(__xludf.DUMMYFUNCTION("""COMPUTED_VALUE"""),"Biotin") -> Biotin | H7: =IFERROR(__xludf.DUMMYFUNCTION("""COMPUTED_VALUE"""),6.0) -> 6 | I7: =IFERROR(__xludf.DUMMYFUNCTION("""COMPUTED_VALUE"""),3.0) -> 3 | J7: =IFERROR(__xludf.DUMMYFUNCTION("""COMPUTED_VALUE"""),FALSE) -> FALSE | K7: =IFERROR(__xludf.DUMMYFUNCTION("""COMPUTED_VALUE"""),FALSE) -> FALSE | M7: =IFERROR(__xludf.DUMMYFUNCTION("""COMPUTED_VALUE"""),"Amitriptyline") -> Amitriptyline | N7: =IFERROR(__xludf.DUMMYFUNCTION("""COMPUTED_VALUE"""),6.0) -> 6 | O7: =IFERROR(__xludf.DUMMYFUNCTION("""COMPUTED_VALUE"""),3.0) -> 3 | P7: =IFERROR(__xludf.DUMMYFUNCTION("""COMPUTED_VALUE"""),FALSE) -> FALSE | Q7: =IFERROR(__xludf.DUMMYFUNCTION("""COMPUTED_VALUE"""),FALSE) -> FALSE | S7: Alfentanil | T7: {=XLOOKUP(S7, MAPK8IP3, B3:B1000, XLOOKUP(S7, ZC4H2, H3:H1000, XLOOKUP(S7, SLC6A1, N3:N1000)))} -> 0 | U7: {=XLOOKUP(S7, MAPK8IP3, C3:C1000, XLOOKUP(S7, ZC4H2, I3:I1000, XLOOKUP(S7, SLC6A1, O3:O1000)))} -> 3 | V7: {=XLOOKUP(S7, MAPK8IP3, D3:D1000, XLOOKUP(S7, ZC4H2, J3:J1000, XLOOKUP(S7, SLC6A1, P3:P1000)))} -> FALSE
A8: =IFERROR(__xludf.DUMMYFUNCTION("""COMPUTED_VALUE"""),"Biotin") -> Biotin | B8: =IFERROR(__xludf.DUMMYFUNCTION("""COMPUTED_VALUE"""),6.0) -> 6 | C8: =IFERROR(__xludf.DUMMYFUNCTION("""COMPUTED_VALUE"""),3.0) -> 3 | D8: =IFERROR(__xludf.DUMMYFUNCTION("""COMPUTED_VALUE"""),FALSE) -> FALSE | E8: =IFERROR(__xludf.DUMMYFUNCTION("""COMPUTED_VALUE"""),FALSE) -> FALSE | G8: =IFERROR(__xludf.DUMMYFUNCTION("""COMPUTED_VALUE"""),"Budesonide") -> Budesonide | H8: =IFERROR(__xludf.DUMMYFUNCTION("""COMPUTED_VALUE"""),6.0) -> 6 | I8: =IFERROR(__xludf.DUMMYFUNCTION("""COMPUTED_VALUE"""),3.0) -> 3 | J8: =IFERROR(__xludf.DUMMYFUNCTION("""COMPUTED_VALUE"""),FALSE) -> FALSE | K8: =IFERROR(__xludf.DUMMYFUNCTION("""COMPUTED_VALUE"""),FALSE) -> FALSE | M8: =IFERROR(__xludf.DUMMYFUNCTION("""COMPUTED_VALUE"""),"Anakinra") -> Anakinra | N8: =IFERROR(__xludf.DUMMYFUNCTION("""COMPUTED_VALUE"""),2.0) -> 2 | O8: =IFERROR(__xludf.DUMMYFUNCTION("""COMPUTED_VALUE"""),3.0) -> 3 | P8: =IFERROR(__xludf.DUMMYFUNCTION("""COMPUTED_VALUE"""),FALSE) -> FALSE | Q8: =IFERROR(__xludf.DUMMYFUNCTION("""COMPUTED_VALUE"""),FALSE) -> FALSE | S8: Amantadine | T8: {=XLOOKUP(S8, MAPK8IP3, B3:B1000, XLOOKUP(S8, ZC4H2, H3:H1000, XLOOKUP(S8, SLC6A1, N3:N1000)))} -> 2 | U8: {=XLOOKUP(S8, MAPK8IP3, C3:C1000, XLOOKUP(S8, ZC4H2, I3:I1000, XLOOKUP(S8, SLC6A1, O3:O1000)))} -> 3 | V8: {=XLOOKUP(S8, MAPK8IP3, D3:D1000, XLOOKUP(S8, ZC4H2, J3:J1000, XLOOKUP(S8, SLC6A1, P3:P1000)))} -> TRUE
A9: =IFERROR(__xludf.DUMMYFUNCTION("""COMPUTED_VALUE"""),"Budesonide") -> Budesonide | B9: =IFERROR(__xludf.DUMMYFUNCTION("""COMPUTED_VALUE"""),6.0) -> 6 | C9: =IFERROR(__xludf.DUMMYFUNCTION("""COMPUTED_VALUE"""),3.0) -> 3 | D9: =IFERROR(__xludf.DUMMYFUNCTION("""COMPUTED_VALUE"""),FALSE) -> FALSE | E9: =IFERROR(__xludf.DUMMYFUNCTION("""COMPUTED_VALUE"""),FALSE) -> FALSE | G9: =IFERROR(__xludf.DUMMYFUNCTION("""COMPUTED_VALUE"""),"Buspirone") -> Buspirone | H9: =IFERROR(__xludf.DUMMYFUNCTION("""COMPUTED_VALUE"""),6.0) -> 6 | I9: =IFERROR(__xludf.DUMMYFUNCTION("""COMPUTED_VALUE"""),3.0) -> 3 | J9: =IFERROR(__xludf.DUMMYFUNCTION("""COMPUTED_VALUE"""),TRUE) -> TRUE | K9: =IFERROR(__xludf.DUMMYFUNCTION("""COMPUTED_VALUE"""),FALSE) -> FALSE | M9: =IFERROR(__xludf.DUMMYFUNCTION("""COMPUTED_VALUE"""),"Arsenic trioxide") -> Arsenic trioxide | N9: =IFERROR(__xludf.DUMMYFUNCTION("""COMPUTED_VALUE"""),1.0) -> 1 | O9: =IFERROR(__xludf.DUMMYFUNCTION("""COMPUTED_VALUE"""),3.0) -> 3 | P9: =IFERROR(__xludf.DUMMYFUNCTION("""COMPUTED_VALUE"""),FALSE) -> FALSE | Q9: =IFERROR(__xludf.DUMMYFUNCTION("""COMPUTED_VALUE"""),FALSE) -> FALSE | S9: Amitriptyline | T9: {=XLOOKUP(S9, MAPK8IP3, B3:B1000, XLOOKUP(S9, ZC4H2, H3:H1000, XLOOKUP(S9, SLC6A1, N3:N1000)))} -> 6 | U9: {=XLOOKUP(S9, MAPK8IP3, C3:C1000, XLOOKUP(S9, ZC4H2, I3:I1000, XLOOKUP(S9, SLC6A1, O3:O1000)))} -> 3 | V9: {=XLOOKUP(S9, MAPK8IP3, D3:D1000, XLOOKUP(S9, ZC4H2, J3:J1000, XLOOKUP(S9, SLC6A1, P3:P1000)))} -> FALSE
A10: =IFERROR(__xludf.DUMMYFUNCTION("""COMPUTED_VALUE"""),"Buspirone") -> Buspirone | B10: =IFERROR(__xludf.DUMMYFUNCTION("""COMPUTED_VALUE"""),6.0) -> 6 | C10: =IFERROR(__xludf.DUMMYFUNCTION("""COMPUTED_VALUE"""),3.0) -> 3 | D10: =IFERROR(__xludf.DUMMYFUNCTION("""COMPUTED_VALUE"""),TRUE) -> TRUE | E10: =IFERROR(__xludf.DUMMYFUNCTION("""COMPUTED_VALUE"""),TRUE) -> TRUE | G10: =IFERROR(__xludf.DUMMYFUNCTION("""COMPUTED_VALUE"""),"Clindamycin") -> Clindamycin | H10: =IFERROR(__xludf.DUMMYFUNCTION("""COMPUTED_VALUE"""),6.0) -> 6 | I10: =IFERROR(__xludf.DUMMYFUNCTION("""COMPUTED_VALUE"""),3.0) -> 3 | J10: =IFERROR(__xludf.DUMMYFUNCTION("""COMPUTED_VALUE"""),FALSE) -> FALSE | K10: =IFERROR(__xludf.DUMMYFUNCTION("""COMPUTED_VALUE"""),FALSE) -> FALSE | M10: =IFERROR(__xludf.DUMMYFUNCTION("""COMPUTED_VALUE"""),"Atomoxetine") -> Atomoxetine | N10: =IFERROR(__xludf.DUMMYFUNCTION("""COMPUTED_VALUE"""),5.0) -> 5 | O10: =IFERROR(__xludf.DUMMYFUNCTION("""COMPUTED_VALUE"""),3.0) -> 3 | P10: =IFERROR(__xludf.DUMMYFUNCTION("""COMPUTED_VALUE"""),FALSE) -> FALSE | Q10: =IFERROR(__xludf.DUMMYFUNCTION("""COMPUTED_VALUE"""),FALSE) -> FALSE | S10: Anakinra | T10: {=XLOOKUP(S10, MAPK8IP3, B3:B1000, XLOOKUP(S10, ZC4H2, H3:H1000, XLOOKUP(S10, SLC6A1, N3:N1000)))} -> 2 | U10: {=XLOOKUP(S10, MAPK8IP3, C3:C1000, XLOOKUP(S10, ZC4H2, I3:I1000, XLOOKUP(S10, SLC6A1, O3:O1000)))} -> 3 | V10: {=XLOOKUP(S10, MAPK8IP3, D3:D1000, XLOOKUP(S10, ZC4H2, J3:J1000, XLOOKUP(S10, SLC6A1, P3:P1000)))} -> FALSE
A11: =IFERROR(__xludf.DUMMYFUNCTION("""COMPUTED_VALUE"""),"Citalopram") -> Citalopram | B11: =IFERROR(__xludf.DUMMYFUNCTION("""COMPUTED_VALUE"""),6.0) -> 6 | C11: =IFERROR(__xludf.DUMMYFUNCTION("""COMPUTED_VALUE"""),3.0) -> 3 | D11: =IFERROR(__xludf.DUMMYFUNCTION("""COMPUTED_VALUE"""),TRUE) -> TRUE | E11: =IFERROR(__xludf.DUMMYFUNCTION("""COMPUTED_VALUE"""),TRUE) -> TRUE | G11: =IFERROR(__xludf.DUMMYFUNCTION("""COMPUTED_VALUE"""),"Clonidine") -> Clonidine | H11: =IFERROR(__xludf.DUMMYFUNCTION("""COMPUTED_VALUE"""),6.0) -> 6 | I11: =IFERROR(__xludf.DUMMYFUNCTION("""COMPUTED_VALUE"""),3.0) -> 3 | J11: =IFERROR(__xludf.DUMMYFUNCTION("""COMPUTED_VALUE"""),FALSE) -> FALSE | K11: =IFERROR(__xludf.DUMMYFUNCTION("""COMPUTED_VALUE"""),FALSE) -> FALSE | M11: =IFERROR(__xludf.DUMMYFUNCTION("""COMPUTED_VALUE"""),"Baclofen") -> Baclofen | N11: =IFERROR(__xludf.DUMMYFUNCTION("""COMPUTED_VALUE"""),3.0) -> 3 | O11: =IFERROR(__xludf.DUMMYFUNCTION("""COMPUTED_VALUE"""),3.0) -> 3 | P11: =IFERROR(__xludf.DUMMYFUNCTION("""COMPUTED_VALUE"""),TRUE) -> TRUE | Q11: =IFERROR(__xludf.DUMMYFUNCTION("""COMPUTED_VALUE"""),FALSE) -> FALSE | S11: Anidulafungin | T11: {=XLOOKUP(S11, MAPK8IP3, B3:B1000, XLOOKUP(S11, ZC4H2, H3:H1000, XLOOKUP(S11, SLC6A1, N3:N1000)))} -> 0 | U11: {=XLOOKUP(S11, MAPK8IP3, C3:C1000, XLOOKUP(S11, ZC4H2, I3:I1000, XLOOKUP(S11, SLC6A1, O3:O1000)))} -> 3 | V11: {=XLOOKUP(S11, MAPK8IP3, D3:D1000, XLOOKUP(S11, ZC4H2, J3:J1000, XLOOKUP(S11, SLC6A1, P3:P1000)))} -> FALSE
A12: =IFERROR(__xludf.DUMMYFUNCTION("""COMPUTED_VALUE"""),"Clonidine") -> Clonidine | B12: =IFERROR(__xludf.DUMMYFUNCTION("""COMPUTED_VALUE"""),6.0) -> 6 | C12: =IFERROR(__xludf.DUMMYFUNCTION("""COMPUTED_VALUE"""),3.0) -> 3 | D12: =IFERROR(__xludf.DUMMYFUNCTION("""COMPUTED_VALUE"""),FALSE) -> FALSE | E12: =IFERROR(__xludf.DUMMYFUNCTION("""COMPUTED_VALUE"""),FALSE) -> FALSE | G12: =IFERROR(__xludf.DUMMYFUNCTION("""COMPUTED_VALUE"""),"Cyproheptadine") -> Cyproheptadine | H12: =IFERROR(__xludf.DUMMYFUNCTION("""COMPUTED_VALUE"""),6.0) -> 6 | I12: =IFERROR(__xludf.DUMMYFUNCTION("""COMPUTED_VALUE"""),3.0) -> 3 | J12: =IFERROR(__xludf.DUMMYFUNCTION("""COMPUTED_VALUE"""),FALSE) -> FALSE | K12: =IFERROR(__xludf.DUMMYFUNCTION("""COMPUTED_VALUE"""),FALSE) -> FALSE | M12: =IFERROR(__xludf.DUMMYFUNCTION("""COMPUTED_VALUE"""),"Betamethasone") -> Betamethasone | N12: =IFERROR(__xludf.DUMMYFUNCTION("""COMPUTED_VALUE"""),6.0) -> 6 | O12: =IFERROR(__xludf.DUMMYFUNCTION("""COMPUTED_VALUE"""),3.0) -> 3 | P12: =IFERROR(__xludf.DUMMYFUNCTION("""COMPUTED_VALUE"""),FALSE) -> FALSE | Q12: =IFERROR(__xludf.DUMMYFUNCTION("""COMPUTED_VALUE"""),FALSE) -> FALSE | S12: Apraclonidine | T12: {=XLOOKUP(S12, MAPK8IP3, B3:B1000, XLOOKUP(S12, ZC4H2, H3:H1000, XLOOKUP(S12, SLC6A1, N3:N1000)))} -> 1 | U12: {=XLOOKUP(S12, MAPK8IP3, C3:C1000, XLOOKUP(S12, ZC4H2, I3:I1000, XLOOKUP(S12, SLC6A1, O3:O1000)))} -> 3 | V12: {=XLOOKUP(S12, MAPK8IP3, D3:D1000, XLOOKUP(S12, ZC4H2, J3:J1000, XLOOKUP(S12, SLC6A1, P3:P1000)))} -> FALSE
A13: =IFERROR(__xludf.DUMMYFUNCTION("""COMPUTED_VALUE"""),"Cyproheptadine") -> Cyproheptadine | B13: =IFERROR(__xludf.DUMMYFUNCTION("""COMPUTED_VALUE"""),6.0) -> 6 | C13: =IFERROR(__xludf.DUMMYFUNCTION("""COMPUTED_VALUE"""),3.0) -> 3 | D13: =IFERROR(__xludf.DUMMYFUNCTION("""COMPUTED_VALUE"""),FALSE) -> FALSE | E13: =IFERROR(__xludf.DUMMYFUNCTION("""COMPUTED_VALUE"""),FALSE) -> FALSE | G13: =IFERROR(__xludf.DUMMYFUNCTION("""COMPUTED_VALUE"""),"Desvenlafaxine") -> Desvenlafaxine | H13: =IFERROR(__xludf.DUMMYFUNCTION("""COMPUTED_VALUE"""),6.0) -> 6 | I13: =IFERROR(__xludf.DUMMYFUNCTION("""COMPUTED_VALUE"""),3.0) -> 3 | J13: =IFERROR(__xludf.DUMMYFUNCTION("""COMPUTED_VALUE"""),FALSE) -> FALSE | K13: =IFERROR(__xludf.DUMMYFUNCTION("""COMPUTED_VALUE"""),FALSE) -> FALSE | M13: =IFERROR(__xludf.DUMMYFUNCTION("""COMPUTED_VALUE"""),"Biotin") -> Biotin | N13: =IFERROR(__xludf.DUMMYFUNCTION("""COMPUTED_VALUE"""),6.0) -> 6 | O13: =IFERROR(__xludf.DUMMYFUNCTION("""COMPUTED_VALUE"""),3.0) -> 3 | P13: =IFERROR(__xludf.DUMMYFUNCTION("""COMPUTED_VALUE"""),FALSE) -> FALSE | Q13: =IFERROR(__xludf.DUMMYFUNCTION("""COMPUTED_VALUE"""),FALSE) -> FALSE | S13: Arsenic trioxide | T13: {=XLOOKUP(S13, MAPK8IP3, B3:B1000, XLOOKUP(S13, ZC4H2, H3:H1000, XLOOKUP(S13, SLC6A1, N3:N1000)))} -> 1 | U13: {=XLOOKUP(S13, MAPK8IP3, C3:C1000, XLOOKUP(S13, ZC4H2, I3:I1000, XLOOKUP(S13, SLC6A1, O3:O1000)))} -> 3 | V13: {=XLOOKUP(S13, MAPK8IP3, D3:D1000, XLOOKUP(S13, ZC4H2, J3:J1000, XLOOKUP(S13, SLC6A1, P3:P1000)))} -> FALSE
A14: =IFERROR(__xludf.DUMMYFUNCTION("""COMPUTED_VALUE"""),"Dantrolene") -> Dantrolene | B14: =IFERROR(__xludf.DUMMYFUNCTION("""COMPUTED_VALUE"""),6.0) -> 6 | C14: =IFERROR(__xludf.DUMMYFUNCTION("""COMPUTED_VALUE"""),3.0) -> 3 | D14: =IFERROR(__xludf.DUMMYFUNCTION("""COMPUTED_VALUE"""),TRUE) -> TRUE | E14: =IFERROR(__xludf.DUMMYFUNCTION("""COMPUTED_VALUE"""),TRUE) -> TRUE | G14: =IFERROR(__xludf.DUMMYFUNCTION("""COMPUTED_VALUE"""),"Escitalopram") -> Escitalopram | H14: =IFERROR(__xludf.DUMMYFUNCTION("""COMPUTED_VALUE"""),6.0) -> 6 | I14: =IFERROR(__xludf.DUMMYFUNCTION("""COMPUTED_VALUE"""),3.0) -> 3 | J14: =IFERROR(__xludf.DUMMYFUNCTION("""COMPUTED_VALUE"""),TRUE) -> TRUE | K14: =IFERROR(__xludf.DUMMYFUNCTION("""COMPUTED_VALUE"""),FALSE) -> FALSE | M14: =IFERROR(__xludf.DUMMYFUNCTION("""COMPUTED_VALUE"""),"Bisoprolol") -> Bisoprolol | N14: =IFERROR(__xludf.DUMMYFUNCTION("""COMPUTED_VALUE"""),2.0) -> 2 | O14: =IFERROR(__xludf.DUMMYFUNCTION("""COMPUTED_VALUE"""),3.0) -> 3 | P14: =IFERROR(__xludf.DUMMYFUNCTION("""COMPUTED_VALUE"""),FALSE) -> FALSE | Q14: =IFERROR(__xludf.DUMMYFUNCTION("""COMPUTED_VALUE"""),FALSE) -> FALSE | S14: Atomoxetine | T14: {=XLOOKUP(S14, MAPK8IP3, B3:B1000, XLOOKUP(S14, ZC4H2, H3:H1000, XLOOKUP(S14, SLC6A1, N3:N1000)))} -> 5 | U14: {=XLOOKUP(S14, MAPK8IP3, C3:C1000, XLOOKUP(S14, ZC4H2, I3:I1000, XLOOKUP(S14, SLC6A1, O3:O1000)))} -> 3 | V14: {=XLOOKUP(S14, MAPK8IP3, D3:D1000, XLOOKUP(S14, ZC4H2, J3:J1000, XLOOKUP(S14, SLC6A1, P3:P1000)))} -> FALSE
A15: =IFERROR(__xludf.DUMMYFUNCTION("""COMPUTED_VALUE"""),"Desvenlafaxine") -> Desvenlafaxine | B15: =IFERROR(__xludf.DUMMYFUNCTION("""COMPUTED_VALUE"""),6.0) -> 6 | C15: =IFERROR(__xludf.DUMMYFUNCTION("""COMPUTED_VALUE"""),3.0) -> 3 | D15: =IFERROR(__xludf.DUMMYFUNCTION("""COMPUTED_VALUE"""),FALSE) -> FALSE | E15: =IFERROR(__xludf.DUMMYFUNCTION("""COMPUTED_VALUE"""),FALSE) -> FALSE | G15: =IFERROR(__xludf.DUMMYFUNCTION("""COMPUTED_VALUE"""),"Fluvoxamine") -> Fluvoxamine | H15: =IFERROR(__xludf.DUMMYFUNCTION("""COMPUTED_VALUE"""),6.0) -> 6 | I15: =IFERROR(__xludf.DUMMYFUNCTION("""COMPUTED_VALUE"""),3.0) -> 3 | J15: =IFERROR(__xludf.DUMMYFUNCTION("""COMPUTED_VALUE"""),TRUE) -> TRUE | K15: =IFERROR(__xludf.DUMMYFUNCTION("""COMPUTED_VALUE"""),FALSE) -> FALSE | M15: =IFERROR(__xludf.DUMMYFUNCTION("""COMPUTED_VALUE"""),"Budesonide") -> Budesonide | N15: =IFERROR(__xludf.DUMMYFUNCTION("""COMPUTED_VALUE"""),6.0) -> 6 | O15: =IFERROR(__xludf.DUMMYFUNCTION("""COMPUTED_VALUE"""),3.0) -> 3 | P15: =IFERROR(__xludf.DUMMYFUNCTION("""COMPUTED_VALUE"""),FALSE) -> FALSE | Q15: =IFERROR(__xludf.DUMMYFUNCTION("""COMPUTED_VALUE"""),FALSE) -> FALSE | S15: Azelaic acid | T15: {=XLOOKUP(S15, MAPK8IP3, B3:B1000, XLOOKUP(S15, ZC4H2, H3:H1000, XLOOKUP(S15, SLC6A1, N3:N1000)))} -> 6 | U15: {=XLOOKUP(S15, MAPK8IP3, C3:C1000, XLOOKUP(S15, ZC4H2, I3:I1000, XLOOKUP(S15, SLC6A1, O3:O1000)))} -> 3 | V15: {=XLOOKUP(S15, MAPK8IP3, D3:D1000, XLOOKUP(S15, ZC4H2, J3:J1000, XLOOKUP(S15, SLC6A1, P3:P1000)))} -> FALSE
A16: =IFERROR(__xludf.DUMMYFUNCTION("""COMPUTED_VALUE"""),"Escitalopram") -> Escitalopram | B16: =IFERROR(__xludf.DUMMYFUNCTION("""COMPUTED_VALUE"""),6.0) -> 6 | C16: =IFERROR(__xludf.DUMMYFUNCTION("""COMPUTED_VALUE"""),3.0) -> 3 | D16: =IFERROR(__xludf.DUMMYFUNCTION("""COMPUTED_VALUE"""),TRUE) -> TRUE | E16: =IFERROR(__xludf.DUMMYFUNCTION("""COMPUTED_VALUE"""),TRUE) -> TRUE | G16: =IFERROR(__xludf.DUMMYFUNCTION("""COMPUTED_VALUE"""),"Gabapentin") -> Gabapentin | H16: =IFERROR(__xludf.DUMMYFUNCTION("""COMPUTED_VALUE"""),6.0) -> 6 | I16: =IFERROR(__xludf.DUMMYFUNCTION("""COMPUTED_VALUE"""),3.0) -> 3 | J16: =IFERROR(__xludf.DUMMYFUNCTION("""COMPUTED_VALUE"""),TRUE) -> TRUE | K16: =IFERROR(__xludf.DUMMYFUNCTION("""COMPUTED_VALUE"""),FALSE) -> FALSE | M16: =IFERROR(__xludf.DUMMYFUNCTION("""COMPUTED_VALUE"""),"Buspirone") -> Buspirone | N16: =IFERROR(__xludf.DUMMYFUNCTION("""COMPUTED_VALUE"""),6.0) -> 6 | O16: =IFERROR(__xludf.DUMMYFUNCTION("""COMPUTED_VALUE"""),3.0) -> 3 | P16: =IFERROR(__xludf.DUMMYFUNCTION("""COMPUTED_VALUE"""),TRUE) -> TRUE | Q16: =IFERROR(__xludf.DUMMYFUNCTION("""COMPUTED_VALUE"""),FALSE) -> FALSE | S16: Baclofen | T16: {=XLOOKUP(S16, MAPK8IP3, B3:B1000, XLOOKUP(S16, ZC4H2, H3:H1000, XLOOKUP(S16, SLC6A1, N3:N1000)))} -> 3 | U16: {=XLOOKUP(S16, MAPK8IP3, C3:C1000, XLOOKUP(S16, ZC4H2, I3:I1000, XLOOKUP(S16, SLC6A1, O3:O1000)))} -> 3 | V16: {=XLOOKUP(S16, MAPK8IP3, D3:D1000, XLOOKUP(S16, ZC4H2, J3:J1000, XLOOKUP(S16, SLC6A1, P3:P1000)))} -> TRUE
A17: =IFERROR(__xludf.DUMMYFUNCTION("""COMPUTED_VALUE"""),"Fluvoxamine") -> Fluvoxamine | B17: =IFERROR(__xludf.DUMMYFUNCTION("""COMPUTED_VALUE"""),6.0) -> 6 | C17: =IFERROR(__xludf.DUMMYFUNCTION("""COMPUTED_VALUE"""),3.0) -> 3 | D17: =IFERROR(__xludf.DUMMYFUNCTION("""COMPUTED_VALUE"""),TRUE) -> TRUE | E17: =IFERROR(__xludf.DUMMYFUNCTION("""COMPUTED_VALUE"""),TRUE) -> TRUE | G17: =IFERROR(__xludf.DUMMYFUNCTION("""COMPUTED_VALUE"""),"Glutamic acid") -> Glutamic acid | H17: =IFERROR(__xludf.DUMMYFUNCTION("""COMPUTED_VALUE"""),6.0) -> 6 | I17: =IFERROR(__xludf.DUMMYFUNCTION("""COMPUTED_VALUE"""),3.0) -> 3 | J17: =IFERROR(__xludf.DUMMYFUNCTION("""COMPUTED_VALUE"""),FALSE) -> FALSE | K17: =IFERROR(__xludf.DUMMYFUNCTION("""COMPUTED_VALUE"""),FALSE) -> FALSE | M17: =IFERROR(__xludf.DUMMYFUNCTION("""COMPUTED_VALUE"""),"Butorphanol") -> Butorphanol | N17: =IFERROR(__xludf.DUMMYFUNCTION("""COMPUTED_VALUE"""),1.0) -> 1 | O17: =IFERROR(__xludf.DUMMYFUNCTION("""COMPUTED_VALUE"""),3.0) -> 3 | P17: =IFERROR(__xludf.DUMMYFUNCTION("""COMPUTED_VALUE"""),FALSE) -> FALSE | Q17: =IFERROR(__xludf.DUMMYFUNCTION("""COMPUTED_VALUE"""),FALSE) -> FALSE | S17: Bepotastine | T17: {=XLOOKUP(S17, MAPK8IP3, B3:B1000, XLOOKUP(S17, ZC4H2, H3:H1000, XLOOKUP(S17, SLC6A1, N3:N1000)))} -> 2 | U17: {=XLOOKUP(S17, MAPK8IP3, C3:C1000, XLOOKUP(S17, ZC4H2, I3:I1000, XLOOKUP(S17, SLC6A1, O3:O1000)))} -> 3 | V17: {=XLOOKUP(S17, MAPK8IP3, D3:D1000, XLOOKUP(S17, ZC4H2, J3:J1000, XLOOKUP(S17, SLC6A1, P3:P1000)))} -> FALSE
A18: =IFERROR(__xludf.DUMMYFUNCTION("""COMPUTED_VALUE"""),"Gabapentin") -> Gabapentin | B18: =IFERROR(__xludf.DUMMYFUNCTION("""COMPUTED_VALUE"""),6.0) -> 6 | C18: =IFERROR(__xludf.DUMMYFUNCTION("""COMPUTED_VALUE"""),3.0) -> 3 | D18: =IFERROR(__xludf.DUMMYFUNCTION("""COMPUTED_VALUE"""),TRUE) -> TRUE | E18: =IFERROR(__xludf.DUMMYFUNCTION("""COMPUTED_VALUE"""),TRUE) -> TRUE | G18: =IFERROR(__xludf.DUMMYFUNCTION("""COMPUTED_VALUE"""),"Hydroxyzine") -> Hydroxyzine | H18: =IFERROR(__xludf.DUMMYFUNCTION("""COMPUTED_VALUE"""),6.0) -> 6 | I18: =IFERROR(__xludf.DUMMYFUNCTION("""COMPUTED_VALUE"""),3.0) -> 3 | J18: =IFERROR(__xludf.DUMMYFUNCTION("""COMPUTED_VALUE"""),FALSE) -> FALSE | K18: =IFERROR(__xludf.DUMMYFUNCTION("""COMPUTED_VALUE"""),FALSE) -> FALSE | M18: =IFERROR(__xludf.DUMMYFUNCTION("""COMPUTED_VALUE"""),"Calcitriol") -> Calcitriol | N18: =IFERROR(__xludf.DUMMYFUNCTION("""COMPUTED_VALUE"""),5.0) -> 5 | O18: =IFERROR(__xludf.DUMMYFUNCTION("""COMPUTED_VALUE"""),3.0) -> 3 | P18: =IFERROR(__xludf.DUMMYFUNCTION("""COMPUTED_VALUE"""),FALSE) -> FALSE | Q18: =IFERROR(__xludf.DUMMYFUNCTION("""COMPUTED_VALUE"""),FALSE) -> FALSE | S18: Betamethasone | T18: {=XLOOKUP(S18, MAPK8IP3, B3:B1000, XLOOKUP(S18, ZC4H2, H3:H1000, XLOOKUP(S18, SLC6A1, N3:N1000)))} -> 6 | U18: {=XLOOKUP(S18, MAPK8IP3, C3:C1000, XLOOKUP(S18, ZC4H2, I3:I1000, XLOOKUP(S18, SLC6A1, O3:O1000)))} -> 3 | V18: {=XLOOKUP(S18, MAPK8IP3, D3:D1000, XLOOKUP(S18, ZC4H2, J3:J1000, XLOOKUP(S18, SLC6A1, P3:P1000)))} -> FALSE
A19: =IFERROR(__xludf.DUMMYFUNCTION("""COMPUTED_VALUE"""),"Glutamic acid") -> Glutamic acid | B19: =IFERROR(__xludf.DUMMYFUNCTION("""COMPUTED_VALUE"""),6.0) -> 6 | C19: =IFERROR(__xludf.DUMMYFUNCTION("""COMPUTED_VALUE"""),3.0) -> 3 | D19: =IFERROR(__xludf.DUMMYFUNCTION("""COMPUTED_VALUE"""),FALSE) -> FALSE | E19: =IFERROR(__xludf.DUMMYFUNCTION("""COMPUTED_VALUE"""),FALSE) -> FALSE | G19: =IFERROR(__xludf.DUMMYFUNCTION("""COMPUTED_VALUE"""),"Loratadine") -> Loratadine | H19: =IFERROR(__xludf.DUMMYFUNCTION("""COMPUTED_VALUE"""),6.0) -> 6 | I19: =IFERROR(__xludf.DUMMYFUNCTION("""COMPUTED_VALUE"""),3.0) -> 3 | J19: =IFERROR(__xludf.DUMMYFUNCTION("""COMPUTED_VALUE"""),FALSE) -> FALSE | K19: =IFERROR(__xludf.DUMMYFUNCTION("""COMPUTED_VALUE"""),FALSE) -> FALSE | M19: =IFERROR(__xludf.DUMMYFUNCTION("""COMPUTED_VALUE"""),"Captopril") -> Captopril | N19: =IFERROR(__xludf.DUMMYFUNCTION("""COMPUTED_VALUE"""),5.0) -> 5 | O19: =IFERROR(__xludf.DUMMYFUNCTION("""COMPUTED_VALUE"""),3.0) -> 3 | P19: =IFERROR(__xludf.DUMMYFUNCTION("""COMPUTED_VALUE"""),TRUE) -> TRUE | Q19: =IFERROR(__xludf.DUMMYFUNCTION("""COMPUTED_VALUE"""),FALSE) -> FALSE | S19: Biotin | T19: {=XLOOKUP(S19, MAPK8IP3, B3:B1000, XLOOKUP(S19, ZC4H2, H3:H1000, XLOOKUP(S19, SLC6A1, N3:N1000)))} -> 6 | U19: {=XLOOKUP(S19, MAPK8IP3, C3:C1000, XLOOKUP(S19, ZC4H2, I3:I1000, XLOOKUP(S19, SLC6A1, O3:O1000)))} -> 3 | V19: {=XLOOKUP(S19, MAPK8IP3, D3:D1000, XLOOKUP(S19, ZC4H2, J3:J1000, XLOOKUP(S19, SLC6A1, P3:P1000)))} -> FALSE
A20: =IFERROR(__xludf.DUMMYFUNCTION("""COMPUTED_VALUE"""),"Loratadine") -> Loratadine | B20: =IFERROR(__xludf.DUMMYFUNCTION("""COMPUTED_VALUE"""),6.0) -> 6 | C20: =IFERROR(__xludf.DUMMYFUNCTION("""COMPUTED_VALUE"""),3.0) -> 3 | D20: =IFERROR(__xludf.DUMMYFUNCTION("""COMPUTED_VALUE"""),FALSE) -> FALSE | E20: =IFERROR(__xludf.DUMMYFUNCTION("""COMPUTED_VALUE"""),FALSE) -> FALSE | G20: =IFERROR(__xludf.DUMMYFUNCTION("""COMPUTED_VALUE"""),"Lovastatin") -> Lovastatin | H20: =IFERROR(__xludf.DUMMYFUNCTION("""COMPUTED_VALUE"""),6.0) -> 6 | I20: =IFERROR(__xludf.DUMMYFUNCTION("""COMPUTED_VALUE"""),3.0) -> 3 | J20: =IFERROR(__xludf.DUMMYFUNCTION("""COMPUTED_VALUE"""),TRUE) -> TRUE | K20: =IFERROR(__xludf.DUMMYFUNCTION("""COMPUTED_VALUE"""),FALSE) -> FALSE | M20: =IFERROR(__xludf.DUMMYFUNCTION("""COMPUTED_VALUE"""),"Chloroprocaine") -> Chloroprocaine | N20: =IFERROR(__xludf.DUMMYFUNCTION("""COMPUTED_VALUE"""),0.0) -> 0 | O20: =IFERROR(__xludf.DUMMYFUNCTION("""COMPUTED_VALUE"""),3.0) -> 3 | P20: =IFERROR(__xludf.DUMMYFUNCTION("""COMPUTED_VALUE"""),FALSE) -> FALSE | Q20: =IFERROR(__xludf.DUMMYFUNCTION("""COMPUTED_VALUE"""),FALSE) -> FALSE | S20: Bisoprolol | T20: {=XLOOKUP(S20, MAPK8IP3, B3:B1000, XLOOKUP(S20, ZC4H2, H3:H1000, XLOOKUP(S20, SLC6A1, N3:N1000)))} -> 2 | U20: {=XLOOKUP(S20, MAPK8IP3, C3:C1000, XLOOKUP(S20, ZC4H2, I3:I1000, XLOOKUP(S20, SLC6A1, O3:O1000)))} -> 3 | V20: {=XLOOKUP(S20, MAPK8IP3, D3:D1000, XLOOKUP(S20, ZC4H2, J3:J1000, XLOOKUP(S20, SLC6A1, P3:P1000)))} -> FALSE
A21: =IFERROR(__xludf.DUMMYFUNCTION("""COMPUTED_VALUE"""),"Lovastatin") -> Lovastatin | B21: =IFERROR(__xludf.DUMMYFUNCTION("""COMPUTED_VALUE"""),6.0) -> 6 | C21: =IFERROR(__xludf.DUMMYFUNCTION("""COMPUTED_VALUE"""),3.0) -> 3 | D21: =IFERROR(__xludf.DUMMYFUNCTION("""COMPUTED_VALUE"""),TRUE) -> TRUE | E21: =IFERROR(__xludf.DUMMYFUNCTION("""COMPUTED_VALUE"""),TRUE) -> TRUE | G21: =IFERROR(__xludf.DUMMYFUNCTION("""COMPUTED_VALUE"""),"Metformin") -> Metformin | H21: =IFERROR(__xludf.DUMMYFUNCTION("""COMPUTED_VALUE"""),6.0) -> 6 | I21: =IFERROR(__xludf.DUMMYFUNCTION("""COMPUTED_VALUE"""),3.0) -> 3 | J21: =IFERROR(__xludf.DUMMYFUNCTION("""COMPUTED_VALUE"""),TRUE) -> TRUE | K21: =IFERROR(__xludf.DUMMYFUNCTION("""COMPUTED_VALUE"""),FALSE) -> FALSE | M21: =IFERROR(__xludf.DUMMYFUNCTION("""COMPUTED_VALUE"""),"Cholecalciferol") -> Cholecalciferol | N21: =IFERROR(__xludf.DUMMYFUNCTION("""COMPUTED_VALUE"""),5.0) -> 5 | O21: =IFERROR(__xludf.DUMMYFUNCTION("""COMPUTED_VALUE"""),3.0) -> 3 | P21: =IFERROR(__xludf.DUMMYFUNCTION("""COMPUTED_VALUE"""),FALSE) -> FALSE | Q21: =IFERROR(__xludf.DUMMYFUNCTION("""COMPUTED_VALUE"""),FALSE) -> FALSE | S21: Budesonide | T21: {=XLOOKUP(S21, MAPK8IP3, B3:B1000, XLOOKUP(S21, ZC4H2, H3:H1000, XLOOKUP(S21, SLC6A1, N3:N1000)))} -> 6 | U21: {=XLOOKUP(S21, MAPK8IP3, C3:C1000, XLOOKUP(S21, ZC4H2, I3:I1000, XLOOKUP(S21, SLC6A1, O3:O1000)))} -> 3 | V21: {=XLOOKUP(S21, MAPK8IP3, D3:D1000, XLOOKUP(S21, ZC4H2, J3:J1000, XLOOKUP(S21, SLC6A1, P3:P1000)))} -> FALSE
A22: =IFERROR(__xludf.DUMMYFUNCTION("""COMPUTED_VALUE"""),"Metformin") -> Metformin | B22: =IFERROR(__xludf.DUMMYFUNCTION("""COMPUTED_VALUE"""),6.0) -> 6 | C22: =IFERROR(__xludf.DUMMYFUNCTION("""COMPUTED_VALUE"""),3.0) -> 3 | D22: =IFERROR(__xludf.DUMMYFUNCTION("""COMPUTED_VALUE"""),TRUE) -> TRUE | E22: =IFERROR(__xludf.DUMMYFUNCTION("""COMPUTED_VALUE"""),TRUE) -> TRUE | G22: =IFERROR(__xludf.DUMMYFUNCTION("""COMPUTED_VALUE"""),"Metoprolol") -> Metoprolol | H22: =IFERROR(__xludf.DUMMYFUNCTION("""COMPUTED_VALUE"""),6.0) -> 6 | I22: =IFERROR(__xludf.DUMMYFUNCTION("""COMPUTED_VALUE"""),3.0) -> 3 | J22: =IFERROR(__xludf.DUMMYFUNCTION("""COMPUTED_VALUE"""),FALSE) -> FALSE | K22: =IFERROR(__xludf.DUMMYFUNCTION("""COMPUTED_VALUE"""),FALSE) -> FALSE | M22: =IFERROR(__xludf.DUMMYFUNCTION("""COMPUTED_VALUE"""),"Ciclesonide") -> Ciclesonide | N22: =IFERROR(__xludf.DUMMYFUNCTION("""COMPUTED_VALUE"""),2.0) -> 2 | O22: =IFERROR(__xludf.DUMMYFUNCTION("""COMPUTED_VALUE"""),3.0) -> 3 | P22: =IFERROR(__xludf.DUMMYFUNCTION("""COMPUTED_VALUE"""),FALSE) -> FALSE | Q22: =IFERROR(__xludf.DUMMYFUNCTION("""COMPUTED_VALUE"""),FALSE) -> FALSE | S22: Buspirone | T22: {=XLOOKUP(S22, MAPK8IP3, B3:B1000, XLOOKUP(S22, ZC4H2, H3:H1000, XLOOKUP(S22, SLC6A1, N3:N1000)))} -> 6 | U22: {=XLOOKUP(S22, MAPK8IP3, C3:C1000, XLOOKUP(S22, ZC4H2, I3:I1000, XLOOKUP(S22, SLC6A1, O3:O1000)))} -> 3 | V22: {=XLOOKUP(S22, MAPK8IP3, D3:D1000, XLOOKUP(S22, ZC4H2, J3:J1000, XLOOKUP(S22, SLC6A1, P3:P1000)))} -> TRUE
A23: =IFERROR(__xludf.DUMMYFUNCTION("""COMPUTED_VALUE"""),"Metoprolol") -> Metoprolol | B23: =IFERROR(__xludf.DUMMYFUNCTION("""COMPUTED_VALUE"""),6.0) -> 6 | C23: =IFERROR(__xludf.DUMMYFUNCTION("""COMPUTED_VALUE"""),3.0) -> 3 | D23: =IFERROR(__xludf.DUMMYFUNCTION("""COMPUTED_VALUE"""),FALSE) -> FALSE | E23: =IFERROR(__xludf.DUMMYFUNCTION("""COMPUTED_VALUE"""),FALSE) -> FALSE | G23: =IFERROR(__xludf.DUMMYFUNCTION("""COMPUTED_VALUE"""),"Oseltamivir") -> Oseltamivir | H23: =IFERROR(__xludf.DUMMYFUNCTION("""COMPUTED_VALUE"""),6.0) -> 6 | I23: =IFERROR(__xludf.DUMMYFUNCTION("""COMPUTED_VALUE"""),3.0) -> 3 | J23: =IFERROR(__xludf.DUMMYFUNCTION("""COMPUTED_VALUE"""),FALSE) -> FALSE | K23: =IFERROR(__xludf.DUMMYFUNCTION("""COMPUTED_VALUE"""),FALSE) -> FALSE | M23: =IFERROR(__xludf.DUMMYFUNCTION("""COMPUTED_VALUE"""),"Ciclopirox") -> Ciclopirox | N23: =IFERROR(__xludf.DUMMYFUNCTION("""COMPUTED_VALUE"""),4.0) -> 4 | O23: =IFERROR(__xludf.DUMMYFUNCTION("""COMPUTED_VALUE"""),3.0) -> 3 | P23: =IFERROR(__xludf.DUMMYFUNCTION("""COMPUTED_VALUE"""),FALSE) -> FALSE | Q23: =IFERROR(__xludf.DUMMYFUNCTION("""COMPUTED_VALUE"""),FALSE) -> FALSE | S23: Butorphanol | T23: {=XLOOKUP(S23, MAPK8IP3, B3:B1000, XLOOKUP(S23, ZC4H2, H3:H1000, XLOOKUP(S23, SLC6A1, N3:N1000)))} -> 1 | U23: {=XLOOKUP(S23, MAPK8IP3, C3:C1000, XLOOKUP(S23, ZC4H2, I3:I1000, XLOOKUP(S23, SLC6A1, O3:O1000)))} -> 3 | V23: {=XLOOKUP(S23, MAPK8IP3, D3:D1000, XLOOKUP(S23, ZC4H2, J3:J1000, XLOOKUP(S23, SLC6A1, P3:P1000)))} -> FALSE
A24: =IFERROR(__xludf.DUMMYFUNCTION("""COMPUTED_VALUE"""),"Oseltamivir") -> Oseltamivir | B24: =IFERROR(__xludf.DUMMYFUNCTION("""COMPUTED_VALUE"""),6.0) -> 6 | C24: =IFERROR(__xludf.DUMMYFUNCTION("""COMPUTED_VALUE"""),3.0) -> 3 | D24: =IFERROR(__xludf.DUMMYFUNCTION("""COMPUTED_VALUE"""),FALSE) -> FALSE | E24: =IFERROR(__xludf.DUMMYFUNCTION("""COMPUTED_VALUE"""),FALSE) -> FALSE | G24: =IFERROR(__xludf.DUMMYFUNCTION("""COMPUTED_VALUE"""),"Potassium chloride") -> Potassium chloride | H24: =IFERROR(__xludf.DUMMYFUNCTION("""COMPUTED_VALUE"""),6.0) -> 6 | I24: =IFERROR(__xludf.DUMMYFUNCTION("""COMPUTED_VALUE"""),3.0) -> 3 | J24: =IFERROR(__xludf.DUMMYFUNCTION("""COMPUTED_VALUE"""),FALSE) -> FALSE | K24: =IFERROR(__xludf.DUMMYFUNCTION("""COMPUTED_VALUE"""),FALSE) -> FALSE | M24: =IFERROR(__xludf.DUMMYFUNCTION("""COMPUTED_VALUE"""),"Cilostazol") -> Cilostazol | N24: =IFERROR(__xludf.DUMMYFUNCTION("""COMPUTED_VALUE"""),1.0) -> 1 | O24: =IFERROR(__xludf.DUMMYFUNCTION("""COMPUTED_VALUE"""),3.0) -> 3 | P24: =IFERROR(__xludf.DUMMYFUNCTION("""COMPUTED_VALUE"""),FALSE) -> FALSE | Q24: =IFERROR(__xludf.DUMMYFUNCTION("""COMPUTED_VALUE"""),FALSE) -> FALSE | S24: Calcitriol | T24: {=XLOOKUP(S24, MAPK8IP3, B3:B1000, XLOOKUP(S24, ZC4H2, H3:H1000, XLOOKUP(S24, SLC6A1, N3:N1000)))} -> 5 | U24: {=XLOOKUP(S24, MAPK8IP3, C3:C1000, XLOOKUP(S24, ZC4H2, I3:I1000, XLOOKUP(S24, SLC6A1, O3:O1000)))} -> 3 | V24: {=XLOOKUP(S24, MAPK8IP3, D3:D1000, XLOOKUP(S24, ZC4H2, J3:J1000, XLOOKUP(S24, SLC6A1, P3:P1000)))} -> FALSE
A25: =IFERROR(__xludf.DUMMYFUNCTION("""COMPUTED_VALUE"""),"Propranolol") -> Propranolol | B25: =IFERROR(__xludf.DUMMYFUNCTION("""COMPUTED_VALUE"""),6.0) -> 6 | C25: =IFERROR(__xludf.DUMMYFUNCTION("""COMPUTED_VALUE"""),3.0) -> 3 | D25: =IFERROR(__xludf.DUMMYFUNCTION("""COMPUTED_VALUE"""),FALSE) -> FALSE | E25: =IFERROR(__xludf.DUMMYFUNCTION("""COMPUTED_VALUE"""),FALSE) -> FALSE | G25: =IFERROR(__xludf.DUMMYFUNCTION("""COMPUTED_VALUE"""),"Propranolol") -> Propranolol | H25: =IFERROR(__xludf.DUMMYFUNCTION("""COMPUTED_VALUE"""),6.0) -> 6 | I25: =IFERROR(__xludf.DUMMYFUNCTION("""COMPUTED_VALUE"""),3.0) -> 3 | J25: =IFERROR(__xludf.DUMMYFUNCTION("""COMPUTED_VALUE"""),FALSE) -> FALSE | K25: =IFERROR(__xludf.DUMMYFUNCTION("""COMPUTED_VALUE"""),FALSE) -> FALSE | M25: =IFERROR(__xludf.DUMMYFUNCTION("""COMPUTED_VALUE"""),"Clemastine") -> Clemastine | N25: =IFERROR(__xludf.DUMMYFUNCTION("""COMPUTED_VALUE"""),3.0) -> 3 | O25: =IFERROR(__xludf.DUMMYFUNCTION("""COMPUTED_VALUE"""),3.0) -> 3 | P25: =IFERROR(__xludf.DUMMYFUNCTION("""COMPUTED_VALUE"""),FALSE) -> FALSE | Q25: =IFERROR(__xludf.DUMMYFUNCTION("""COMPUTED_VALUE"""),FALSE) -> FALSE | S25: Captopril | T25: {=XLOOKUP(S25, MAPK8IP3, B3:B1000, XLOOKUP(S25, ZC4H2, H3:H1000, XLOOKUP(S25, SLC6A1, N3:N1000)))} -> 5 | U25: {=XLOOKUP(S25, MAPK8IP3, C3:C1000, XLOOKUP(S25, ZC4H2, I3:I1000, XLOOKUP(S25, SLC6A1, O3:O1000)))} -> 3 | V25: {=XLOOKUP(S25, MAPK8IP3, D3:D1000, XLOOKUP(S25, ZC4H2, J3:J1000, XLOOKUP(S25, SLC6A1, P3:P1000)))} -> TRUE
A26: =IFERROR(__xludf.DUMMYFUNCTION("""COMPUTED_VALUE"""),"Pyridoxine") -> Pyridoxine | B26: =IFERROR(__xludf.DUMMYFUNCTION("""COMPUTED_VALUE"""),6.0) -> 6 | C26: =IFERROR(__xludf.DUMMYFUNCTION("""COMPUTED_VALUE"""),3.0) -> 3 | D26: =IFERROR(__xludf.DUMMYFUNCTION("""COMPUTED_VALUE"""),FALSE) -> FALSE | E26: =IFERROR(__xludf.DUMMYFUNCTION("""COMPUTED_VALUE"""),FALSE) -> FALSE | G26: =IFERROR(__xludf.DUMMYFUNCTION("""COMPUTED_VALUE"""),"Pyridoxine") -> Pyridoxine | H26: =IFERROR(__xludf.DUMMYFUNCTION("""COMPUTED_VALUE"""),6.0) -> 6 | I26: =IFERROR(__xludf.DUMMYFUNCTION("""COMPUTED_VALUE"""),3.0) -> 3 | J26: =IFERROR(__xludf.DUMMYFUNCTION("""COMPUTED_VALUE"""),FALSE) -> FALSE | K26: =IFERROR(__xludf.DUMMYFUNCTION("""COMPUTED_VALUE"""),FALSE) -> FALSE | M26: =IFERROR(__xludf.DUMMYFUNCTION("""COMPUTED_VALUE"""),"Clomifene") -> Clomifene | N26: =IFERROR(__xludf.DUMMYFUNCTION("""COMPUTED_VALUE"""),0.0) -> 0 | O26: =IFERROR(__xludf.DUMMYFUNCTION("""COMPUTED_VALUE"""),3.0) -> 3 | P26: =IFERROR(__xludf.DUMMYFUNCTION("""COMPUTED_VALUE"""),FALSE) -> FALSE | Q26: =IFERROR(__xludf.DUMMYFUNCTION("""COMPUTED_VALUE"""),FALSE) -> FALSE | S26: Cefoperazone | T26: {=XLOOKUP(S26, MAPK8IP3, B3:B1000, XLOOKUP(S26, ZC4H2, H3:H1000, XLOOKUP(S26, SLC6A1, N3:N1000)))} -> 2 | U26: {=XLOOKUP(S26, MAPK8IP3, C3:C1000, XLOOKUP(S26, ZC4H2, I3:I1000, XLOOKUP(S26, SLC6A1, O3:O1000)))} -> 2 | V26: {=XLOOKUP(S26, MAPK8IP3, D3:D1000, XLOOKUP(S26, ZC4H2, J3:J1000, XLOOKUP(S26, SLC6A1, P3:P1000)))} -> TRUE
A27: =IFERROR(__xludf.DUMMYFUNCTION("""COMPUTED_VALUE"""),"Sertraline") -> Sertraline | B27: =IFERROR(__xludf.DUMMYFUNCTION("""COMPUTED_VALUE"""),6.0) -> 6 | C27: =IFERROR(__xludf.DUMMYFUNCTION("""COMPUTED_VALUE"""),3.0) -> 3 | D27: =IFERROR(__xludf.DUMMYFUNCTION("""COMPUTED_VALUE"""),TRUE) -> TRUE | E27: =IFERROR(__xludf.DUMMYFUNCTION("""COMPUTED_VALUE"""),TRUE) -> TRUE | G27: =IFERROR(__xludf.DUMMYFUNCTION("""COMPUTED_VALUE"""),"Sertraline") -> Sertraline | H27: =IFERROR(__xludf.DUMMYFUNCTION("""COMPUTED_VALUE"""),6.0) -> 6 | I27: =IFERROR(__xludf.DUMMYFUNCTION("""COMPUTED_VALUE"""),3.0) -> 3 | J27: =IFERROR(__xludf.DUMMYFUNCTION("""COMPUTED_VALUE"""),TRUE) -> TRUE | K27: =IFERROR(__xludf.DUMMYFUNCTION("""COMPUTED_VALUE"""),FALSE) -> FALSE | M27: =IFERROR(__xludf.DUMMYFUNCTION("""COMPUTED_VALUE"""),"Clonidine") -> Clonidine | N27: =IFERROR(__xludf.DUMMYFUNCTION("""COMPUTED_VALUE"""),6.0) -> 6 | O27: =IFERROR(__xludf.DUMMYFUNCTION("""COMPUTED_VALUE"""),3.0) -> 3 | P27: =IFERROR(__xludf.DUMMYFUNCTION("""COMPUTED_VALUE"""),FALSE) -> FALSE | Q27: =IFERROR(__xludf.DUMMYFUNCTION("""COMPUTED_VALUE"""),FALSE) -> FALSE | S27: Chloroprocaine | T27: {=XLOOKUP(S27, MAPK8IP3, B3:B1000, XLOOKUP(S27, ZC4H2, H3:H1000, XLOOKUP(S27, SLC6A1, N3:N1000)))} -> 0 | U27: {=XLOOKUP(S27, MAPK8IP3, C3:C1000, XLOOKUP(S27, ZC4H2, I3:I1000, XLOOKUP(S27, SLC6A1, O3:O1000)))} -> 3 | V27: {=XLOOKUP(S27, MAPK8IP3, D3:D1000, XLOOKUP(S27, ZC4H2, J3:J1000, XLOOKUP(S27, SLC6A1, P3:P1000)))} -> FALSE
A28: =IFERROR(__xludf.DUMMYFUNCTION("""COMPUTED_VALUE"""),"Triamcinolone") -> Triamcinolone | B28: =IFERROR(__xludf.DUMMYFUNCTION("""COMPUTED_VALUE"""),6.0) -> 6 | C28: =IFERROR(__xludf.DUMMYFUNCTION("""COMPUTED_VALUE"""),3.0) -> 3 | D28: =IFERROR(__xludf.DUMMYFUNCTION("""COMPUTED_VALUE"""),FALSE) -> FALSE | E28: =IFERROR(__xludf.DUMMYFUNCTION("""COMPUTED_VALUE"""),FALSE) -> FALSE | G28: =IFERROR(__xludf.DUMMYFUNCTION("""COMPUTED_VALUE"""),"Triamcinolone") -> Triamcinolone | H28: =IFERROR(__xludf.DUMMYFUNCTION("""COMPUTED_VALUE"""),6.0) -> 6 | I28: =IFERROR(__xludf.DUMMYFUNCTION("""COMPUTED_VALUE"""),3.0) -> 3 | J28: =IFERROR(__xludf.DUMMYFUNCTION("""COMPUTED_VALUE"""),FALSE) -> FALSE | K28: =IFERROR(__xludf.DUMMYFUNCTION("""COMPUTED_VALUE"""),FALSE) -> FALSE | M28: =IFERROR(__xludf.DUMMYFUNCTION("""COMPUTED_VALUE"""),"Cyproheptadine") -> Cyproheptadine | N28: =IFERROR(__xludf.DUMMYFUNCTION("""COMPUTED_VALUE"""),6.0) -> 6 | O28: =IFERROR(__xludf.DUMMYFUNCTION("""COMPUTED_VALUE"""),3.0) -> 3 | P28: =IFERROR(__xludf.DUMMYFUNCTION("""COMPUTED_VALUE"""),FALSE) -> FALSE | Q28: =IFERROR(__xludf.DUMMYFUNCTION("""COMPUTED_VALUE"""),FALSE) -> FALSE | S28: Cholecalciferol | T28: {=XLOOKUP(S28, MAPK8IP3, B3:B1000, XLOOKUP(S28, ZC4H2, H3:H1000, XLOOKUP(S28, SLC6A1, N3:N1000)))} -> 5 | U28: {=XLOOKUP(S28, MAPK8IP3, C3:C1000, XLOOKUP(S28, ZC4H2, I3:I1000, XLOOKUP(S28, SLC6A1, O3:O1000)))} -> 3 | V28: {=XLOOKUP(S28, MAPK8IP3, D3:D1000, XLOOKUP(S28, ZC4H2, J3:J1000, XLOOKUP(S28, SLC6A1, P3:P1000)))} -> FALSE
A29: =IFERROR(__xludf.DUMMYFUNCTION("""COMPUTED_VALUE"""),"Atomoxetine") -> Atomoxetine | B29: =IFERROR(__xludf.DUMMYFUNCTION("""COMPUTED_VALUE"""),5.0) -> 5 | C29: =IFERROR(__xludf.DUMMYFUNCTION("""COMPUTED_VALUE"""),3.0) -> 3 | D29: =IFERROR(__xludf.DUMMYFUNCTION("""COMPUTED_VALUE"""),FALSE) -> FALSE | E29: =IFERROR(__xludf.DUMMYFUNCTION("""COMPUTED_VALUE"""),FALSE) -> FALSE | G29: =IFERROR(__xludf.DUMMYFUNCTION("""COMPUTED_VALUE"""),"Atomoxetine") -> Atomoxetine | H29: =IFERROR(__xludf.DUMMYFUNCTION("""COMPUTED_VALUE"""),5.0) -> 5 | I29: =IFERROR(__xludf.DUMMYFUNCTION("""COMPUTED_VALUE"""),3.0) -> 3 | J29: =IFERROR(__xludf.DUMMYFUNCTION("""COMPUTED_VALUE"""),FALSE) -> FALSE | K29: =IFERROR(__xludf.DUMMYFUNCTION("""COMPUTED_VALUE"""),FALSE) -> FALSE | M29: =IFERROR(__xludf.DUMMYFUNCTION("""COMPUTED_VALUE"""),"Desflurane") -> Desflurane | N29: =IFERROR(__xludf.DUMMYFUNCTION("""COMPUTED_VALUE"""),0.0) -> 0 | O29: =IFERROR(__xludf.DUMMYFUNCTION("""COMPUTED_VALUE"""),3.0) -> 3 | P29: =IFERROR(__xludf.DUMMYFUNCTION("""COMPUTED_VALUE"""),FALSE) -> FALSE | Q29: =IFERROR(__xludf.DUMMYFUNCTION("""COMPUTED_VALUE"""),FALSE) -> FALSE | S29: Ciclesonide | T29: {=XLOOKUP(S29, MAPK8IP3, B3:B1000, XLOOKUP(S29, ZC4H2, H3:H1000, XLOOKUP(S29, SLC6A1, N3:N1000)))} -> 2 | U29: {=XLOOKUP(S29, MAPK8IP3, C3:C1000, XLOOKUP(S29, ZC4H2, I3:I1000, XLOOKUP(S29, SLC6A1, O3:O1000)))} -> 3 | V29: {=XLOOKUP(S29, MAPK8IP3, D3:D1000, XLOOKUP(S29, ZC4H2, J3:J1000, XLOOKUP(S29, SLC6A1, P3:P1000)))} -> FALSE
A30: =IFERROR(__xludf.DUMMYFUNCTION("""COMPUTED_VALUE"""),"Calcitriol") -> Calcitriol | B30: =IFERROR(__xludf.DUMMYFUNCTION("""COMPUTED_VALUE"""),5.0) -> 5 | C30: =IFERROR(__xludf.DUMMYFUNCTION("""COMPUTED_VALUE"""),3.0) -> 3 | D30: =IFERROR(__xludf.DUMMYFUNCTION("""COMPUTED_VALUE"""),FALSE) -> FALSE | E30: =IFERROR(__xludf.DUMMYFUNCTION("""COMPUTED_VALUE"""),FALSE) -> FALSE | G30: =IFERROR(__xludf.DUMMYFUNCTION("""COMPUTED_VALUE"""),"Calcitriol") -> Calcitriol | H30: =IFERROR(__xludf.DUMMYFUNCTION("""COMPUTED_VALUE"""),5.0) -> 5 | I30: =IFERROR(__xludf.DUMMYFUNCTION("""COMPUTED_VALUE"""),3.0) -> 3 | J30: =IFERROR(__xludf.DUMMYFUNCTION("""COMPUTED_VALUE"""),FALSE) -> FALSE | K30: =IFERROR(__xludf.DUMMYFUNCTION("""COMPUTED_VALUE"""),FALSE) -> FALSE | M30: =IFERROR(__xludf.DUMMYFUNCTION("""COMPUTED_VALUE"""),"Desonide") -> Desonide | N30: =IFERROR(__xludf.DUMMYFUNCTION("""COMPUTED_VALUE"""),5.0) -> 5 | O30: =IFERROR(__xludf.DUMMYFUNCTION("""COMPUTED_VALUE"""),3.0) -> 3 | P30: =IFERROR(__xludf.DUMMYFUNCTION("""COMPUTED_VALUE"""),FALSE) -> FALSE | Q30: =IFERROR(__xludf.DUMMYFUNCTION("""COMPUTED_VALUE"""),FALSE) -> FALSE | S30: Ciclopirox | T30: {=XLOOKUP(S30, MAPK8IP3, B3:B1000, XLOOKUP(S30, ZC4H2, H3:H1000, XLOOKUP(S30, SLC6A1, N3:N1000)))} -> 4 | U30: {=XLOOKUP(S30, MAPK8IP3, C3:C1000, XLOOKUP(S30, ZC4H2, I3:I1000, XLOOKUP(S30, SLC6A1, O3:O1000)))} -> 3 | V30: {=XLOOKUP(S30, MAPK8IP3, D3:D1000, XLOOKUP(S30, ZC4H2, J3:J1000, XLOOKUP(S30, SLC6A1, P3:P1000)))} -> FALSE
A31: =IFERROR(__xludf.DUMMYFUNCTION("""COMPUTED_VALUE"""),"Captopril") -> Captopril | B31: =IFERROR(__xludf.DUMMYFUNCTION("""COMPUTED_VALUE"""),5.0) -> 5 | C31: =IFERROR(__xludf.DUMMYFUNCTION("""COMPUTED_VALUE"""),3.0) -> 3 | D31: =IFERROR(__xludf.DUMMYFUNCTION("""COMPUTED_VALUE"""),TRUE) -> TRUE | E31: =IFERROR(__xludf.DUMMYFUNCTION("""COMPUTED_VALUE"""),TRUE) -> TRUE | G31: =IFERROR(__xludf.DUMMYFUNCTION("""COMPUTED_VALUE"""),"Captopril") -> Captopril | H31: =IFERROR(__xludf.DUMMYFUNCTION("""COMPUTED_VALUE"""),5.0) -> 5 | I31: =IFERROR(__xludf.DUMMYFUNCTION("""COMPUTED_VALUE"""),3.0) -> 3 | J31: =IFERROR(__xludf.DUMMYFUNCTION("""COMPUTED_VALUE"""),TRUE) -> TRUE | K31: =IFERROR(__xludf.DUMMYFUNCTION("""COMPUTED_VALUE"""),FALSE) -> FALSE | M31: =IFERROR(__xludf.DUMMYFUNCTION("""COMPUTED_VALUE"""),"Desvenlafaxine") -> Desvenlafaxine | N31: =IFERROR(__xludf.DUMMYFUNCTION("""COMPUTED_VALUE"""),6.0) -> 6 | O31: =IFERROR(__xludf.DUMMYFUNCTION("""COMPUTED_VALUE"""),3.0) -> 3 | P31: =IFERROR(__xludf.DUMMYFUNCTION("""COMPUTED_VALUE"""),FALSE) -> FALSE | Q31: =IFERROR(__xludf.DUMMYFUNCTION("""COMPUTED_VALUE"""),FALSE) -> FALSE | S31: Cilostazol | T31: {=XLOOKUP(S31, MAPK8IP3, B3:B1000, XLOOKUP(S31, ZC4H2, H3:H1000, XLOOKUP(S31, SLC6A1, N3:N1000)))} -> 1 | U31: {=XLOOKUP(S31, MAPK8IP3, C3:C1000, XLOOKUP(S31, ZC4H2, I3:I1000, XLOOKUP(S31, SLC6A1, O3:O1000)))} -> 3 | V31: {=XLOOKUP(S31, MAPK8IP3, D3:D1000, XLOOKUP(S31, ZC4H2, J3:J1000, XLOOKUP(S31, SLC6A1, P3:P1000)))} -> FALSE
A32: =IFERROR(__xludf.DUMMYFUNCTION("""COMPUTED_VALUE"""),"Cholecalciferol") -> Cholecalciferol | B32: =IFERROR(__xludf.DUMMYFUNCTION("""COMPUTED_VALUE"""),5.0) -> 5 | C32: =IFERROR(__xludf.DUMMYFUNCTION("""COMPUTED_VALUE"""),3.0) -> 3 | D32: =IFERROR(__xludf.DUMMYFUNCTION("""COMPUTED_VALUE"""),FALSE) -> FALSE | E32: =IFERROR(__xludf.DUMMYFUNCTION("""COMPUTED_VALUE"""),FALSE) -> FALSE | G32: =IFERROR(__xludf.DUMMYFUNCTION("""COMPUTED_VALUE"""),"Cholecalciferol") -> Cholecalciferol | H32: =IFERROR(__xludf.DUMMYFUNCTION("""COMPUTED_VALUE"""),5.0) -> 5 | I32: =IFERROR(__xludf.DUMMYFUNCTION("""COMPUTED_VALUE"""),3.0) -> 3 | J32: =IFERROR(__xludf.DUMMYFUNCTION("""COMPUTED_VALUE"""),FALSE) -> FALSE | K32: =IFERROR(__xludf.DUMMYFUNCTION("""COMPUTED_VALUE"""),FALSE) -> FALSE | M32: =IFERROR(__xludf.DUMMYFUNCTION("""COMPUTED_VALUE"""),"Dexmedetomidine") -> Dexmedetomidine | N32: =IFERROR(__xludf.DUMMYFUNCTION("""COMPUTED_VALUE"""),2.0) -> 2 | O32: =IFERROR(__xludf.DUMMYFUNCTION("""COMPUTED_VALUE"""),3.0) -> 3 | P32: =IFERROR(__xludf.DUMMYFUNCTION("""COMPUTED_VALUE"""),FALSE) -> FALSE | Q32: =IFERROR(__xludf.DUMMYFUNCTION("""COMPUTED_VALUE"""),FALSE) -> FALSE | S32: Citalopram | T32: {=XLOOKUP(S32, MAPK8IP3, B3:B1000, XLOOKUP(S32, ZC4H2, H3:H1000, XLOOKUP(S32, SLC6A1, N3:N1000)))} -> 6 | U32: {=XLOOKUP(S32, MAPK8IP3, C3:C1000, XLOOKUP(S32, ZC4H2, I3:I1000, XLOOKUP(S32, SLC6A1, O3:O1000)))} -> 3 | V32: {=XLOOKUP(S32, MAPK8IP3, D3:D1000, XLOOKUP(S32, ZC4H2, J3:J1000, XLOOKUP(S32, SLC6A1, P3:P1000)))} -> TRUE
A33: =IFERROR(__xludf.DUMMYFUNCTION("""COMPUTED_VALUE"""),"Desloratadine") -> Desloratadine | B33: =IFERROR(__xludf.DUMMYFUNCTION("""COMPUTED_VALUE"""),5.0) -> 5 | C33: =IFERROR(__xludf.DUMMYFUNCTION("""COMPUTED_VALUE"""),3.0) -> 3 | D33: =IFERROR(__xludf.DUMMYFUNCTION("""COMPUTED_VALUE"""),FALSE) -> FALSE | E33: =IFERROR(__xludf.DUMMYFUNCTION("""COMPUTED_VALUE"""),FALSE) -> FALSE | G33: =IFERROR(__xludf.DUMMYFUNCTION("""COMPUTED_VALUE"""),"Desloratadine") -> Desloratadine | H33: =IFERROR(__xludf.DUMMYFUNCTION("""COMPUTED_VALUE"""),5.0) -> 5 | I33: =IFERROR(__xludf.DUMMYFUNCTION("""COMPUTED_VALUE"""),3.0) -> 3 | J33: =IFERROR(__xludf.DUMMYFUNCTION("""COMPUTED_VALUE"""),FALSE) -> FALSE | K33: =IFERROR(__xludf.DUMMYFUNCTION("""COMPUTED_VALUE"""),FALSE) -> FALSE | M33: =IFERROR(__xludf.DUMMYFUNCTION("""COMPUTED_VALUE"""),"Dextromethorphan") -> Dextromethorphan | N33: =IFERROR(__xludf.DUMMYFUNCTION("""COMPUTED_VALUE"""),5.0) -> 5 | O33: =IFERROR(__xludf.DUMMYFUNCTION("""COMPUTED_VALUE"""),3.0) -> 3 | P33: =IFERROR(__xludf.DUMMYFUNCTION("""COMPUTED_VALUE"""),FALSE) -> FALSE | Q33: =IFERROR(__xludf.DUMMYFUNCTION("""COMPUTED_VALUE"""),FALSE) -> FALSE | S33: Clemastine | T33: {=XLOOKUP(S33, MAPK8IP3, B3:B1000, XLOOKUP(S33, ZC4H2, H3:H1000, XLOOKUP(S33, SLC6A1, N3:N1000)))} -> 3 | U33: {=XLOOKUP(S33, MAPK8IP3, C3:C1000, XLOOKUP(S33, ZC4H2, I3:I1000, XLOOKUP(S33, SLC6A1, O3:O1000)))} -> 3 | V33: {=XLOOKUP(S33, MAPK8IP3, D3:D1000, XLOOKUP(S33, ZC4H2, J3:J1000, XLOOKUP(S33, SLC6A1, P3:P1000)))} -> FALSE
A34: =IFERROR(__xludf.DUMMYFUNCTION("""COMPUTED_VALUE"""),"Dextromethorphan") -> Dextromethorphan | B34: =IFERROR(__xludf.DUMMYFUNCTION("""COMPUTED_VALUE"""),5.0) -> 5 | C34: =IFERROR(__xludf.DUMMYFUNCTION("""COMPUTED_VALUE"""),3.0) -> 3 | D34: =IFERROR(__xludf.DUMMYFUNCTION("""COMPUTED_VALUE"""),FALSE) -> FALSE | E34: =IFERROR(__xludf.DUMMYFUNCTION("""COMPUTED_VALUE"""),FALSE) -> FALSE | G34: =IFERROR(__xludf.DUMMYFUNCTION("""COMPUTED_VALUE"""),"Dextromethorphan") -> Dextromethorphan | H34: =IFERROR(__xludf.DUMMYFUNCTION("""COMPUTED_VALUE"""),5.0) -> 5 | I34: =IFERROR(__xludf.DUMMYFUNCTION("""COMPUTED_VALUE"""),3.0) -> 3 | J34: =IFERROR(__xludf.DUMMYFUNCTION("""COMPUTED_VALUE"""),FALSE) -> FALSE | K34: =IFERROR(__xludf.DUMMYFUNCTION("""COMPUTED_VALUE"""),FALSE) -> FALSE | M34: =IFERROR(__xludf.DUMMYFUNCTION("""COMPUTED_VALUE"""),"Disopyramide") -> Disopyramide | N34: =IFERROR(__xludf.DUMMYFUNCTION("""COMPUTED_VALUE"""),1.0) -> 1 | O34: =IFERROR(__xludf.DUMMYFUNCTION("""COMPUTED_VALUE"""),3.0) -> 3 | P34: =IFERROR(__xludf.DUMMYFUNCTION("""COMPUTED_VALUE"""),FALSE) -> FALSE | Q34: =IFERROR(__xludf.DUMMYFUNCTION("""COMPUTED_VALUE"""),FALSE) -> FALSE | S34: Clindamycin | T34: {=XLOOKUP(S34, MAPK8IP3, B3:B1000, XLOOKUP(S34, ZC4H2, H3:H1000, XLOOKUP(S34, SLC6A1, N3:N1000)))} -> 6 | U34: {=XLOOKUP(S34, MAPK8IP3, C3:C1000, XLOOKUP(S34, ZC4H2, I3:I1000, XLOOKUP(S34, SLC6A1, O3:O1000)))} -> 3 | V34: {=XLOOKUP(S34, MAPK8IP3, D3:D1000, XLOOKUP(S34, ZC4H2, J3:J1000, XLOOKUP(S34, SLC6A1, P3:P1000)))} -> FALSE
A35: =IFERROR(__xludf.DUMMYFUNCTION("""COMPUTED_VALUE"""),"Ezetimibe") -> Ezetimibe | B35: =IFERROR(__xludf.DUMMYFUNCTION("""COMPUTED_VALUE"""),5.0) -> 5 | C35: =IFERROR(__xludf.DUMMYFUNCTION("""COMPUTED_VALUE"""),3.0) -> 3 | D35: =IFERROR(__xludf.DUMMYFUNCTION("""COMPUTED_VALUE"""),FALSE) -> FALSE | E35: =IFERROR(__xludf.DUMMYFUNCTION("""COMPUTED_VALUE"""),FALSE) -> FALSE | G35: =IFERROR(__xludf.DUMMYFUNCTION("""COMPUTED_VALUE"""),"Fexofenadine") -> Fexofenadine | H35: =IFERROR(__xludf.DUMMYFUNCTION("""COMPUTED_VALUE"""),5.0) -> 5 | I35: =IFERROR(__xludf.DUMMYFUNCTION("""COMPUTED_VALUE"""),3.0) -> 3 | J35: =IFERROR(__xludf.DUMMYFUNCTION("""COMPUTED_VALUE"""),FALSE) -> FALSE | K35: =IFERROR(__xludf.DUMMYFUNCTION("""COMPUTED_VALUE"""),FALSE) -> FALSE | M35: =IFERROR(__xludf.DUMMYFUNCTION("""COMPUTED_VALUE"""),"Eplerenone") -> Eplerenone | N35: =IFERROR(__xludf.DUMMYFUNCTION("""COMPUTED_VALUE"""),2.0) -> 2 | O35: =IFERROR(__xludf.DUMMYFUNCTION("""COMPUTED_VALUE"""),3.0) -> 3 | P35: =IFERROR(__xludf.DUMMYFUNCTION("""COMPUTED_VALUE"""),FALSE) -> FALSE | Q35: =IFERROR(__xludf.DUMMYFUNCTION("""COMPUTED_VALUE"""),FALSE) -> FALSE | S35: Clomifene | T35: {=XLOOKUP(S35, MAPK8IP3, B3:B1000, XLOOKUP(S35, ZC4H2, H3:H1000, XLOOKUP(S35, SLC6A1, N3:N1000)))} -> 0 | U35: {=XLOOKUP(S35, MAPK8IP3, C3:C1000, XLOOKUP(S35, ZC4H2, I3:I1000, XLOOKUP(S35, SLC6A1, O3:O1000)))} -> 3 | V35: {=XLOOKUP(S35, MAPK8IP3, D3:D1000, XLOOKUP(S35, ZC4H2, J3:J1000, XLOOKUP(S35, SLC6A1, P3:P1000)))} -> FALSE
A36: =IFERROR(__xludf.DUMMYFUNCTION("""COMPUTED_VALUE"""),"Fexofenadine") -> Fexofenadine | B36: =IFERROR(__xludf.DUMMYFUNCTION("""COMPUTED_VALUE"""),5.0) -> 5 | C36: =IFERROR(__xludf.DUMMYFUNCTION("""COMPUTED_VALUE"""),3.0) -> 3 | D36: =IFERROR(__xludf.DUMMYFUNCTION("""COMPUTED_VALUE"""),FALSE) -> FALSE | E36: =IFERROR(__xludf.DUMMYFUNCTION("""COMPUTED_VALUE"""),FALSE) -> FALSE | G36: =IFERROR(__xludf.DUMMYFUNCTION("""COMPUTED_VALUE"""),"Lidocaine") -> Lidocaine | H36: =IFERROR(__xludf.DUMMYFUNCTION("""COMPUTED_VALUE"""),5.0) -> 5 | I36: =IFERROR(__xludf.DUMMYFUNCTION("""COMPUTED_VALUE"""),3.0) -> 3 | J36: =IFERROR(__xludf.DUMMYFUNCTION("""COMPUTED_VALUE"""),FALSE) -> FALSE | K36: =IFERROR(__xludf.DUMMYFUNCTION("""COMPUTED_VALUE"""),FALSE) -> FALSE | M36: =IFERROR(__xludf.DUMMYFUNCTION("""COMPUTED_VALUE"""),"Escitalopram") -> Escitalopram | N36: =IFERROR(__xludf.DUMMYFUNCTION("""COMPUTED_VALUE"""),6.0) -> 6 | O36: =IFERROR(__xludf.DUMMYFUNCTION("""COMPUTED_VALUE"""),3.0) -> 3 | P36: =IFERROR(__xludf.DUMMYFUNCTION("""COMPUTED_VALUE"""),TRUE) -> TRUE | Q36: =IFERROR(__xludf.DUMMYFUNCTION("""COMPUTED_VALUE"""),FALSE) -> FALSE | S36: Clonidine | T36: {=XLOOKUP(S36, MAPK8IP3, B3:B1000, XLOOKUP(S36, ZC4H2, H3:H1000, XLOOKUP(S36, SLC6A1, N3:N1000)))} -> 6 | U36: {=XLOOKUP(S36, MAPK8IP3, C3:C1000, XLOOKUP(S36, ZC4H2, I3:I1000, XLOOKUP(S36, SLC6A1, O3:O1000)))} -> 3 | V36: {=XLOOKUP(S36, MAPK8IP3, D3:D1000, XLOOKUP(S36, ZC4H2, J3:J1000, XLOOKUP(S36, SLC6A1, P3:P1000)))} -> FALSE
A37: =IFERROR(__xludf.DUMMYFUNCTION("""COMPUTED_VALUE"""),"Gemfibrozil") -> Gemfibrozil | B37: =IFERROR(__xludf.DUMMYFUNCTION("""COMPUTED_VALUE"""),5.0) -> 5 | C37: =IFERROR(__xludf.DUMMYFUNCTION("""COMPUTED_VALUE"""),3.0) -> 3 | D37: =IFERROR(__xludf.DUMMYFUNCTION("""COMPUTED_VALUE"""),FALSE) -> FALSE | E37: =IFERROR(__xludf.DUMMYFUNCTION("""COMPUTED_VALUE"""),FALSE) -> FALSE | G37: =IFERROR(__xludf.DUMMYFUNCTION("""COMPUTED_VALUE"""),"Midodrine") -> Midodrine | H37: =IFERROR(__xludf.DUMMYFUNCTION("""COMPUTED_VALUE"""),5.0) -> 5 | I37: =IFERROR(__xludf.DUMMYFUNCTION("""COMPUTED_VALUE"""),3.0) -> 3 | J37: =IFERROR(__xludf.DUMMYFUNCTION("""COMPUTED_VALUE"""),FALSE) -> FALSE | K37: =IFERROR(__xludf.DUMMYFUNCTION("""COMPUTED_VALUE"""),FALSE) -> FALSE | M37: =IFERROR(__xludf.DUMMYFUNCTION("""COMPUTED_VALUE"""),"Ethosuximide") -> Ethosuximide | N37: =IFERROR(__xludf.DUMMYFUNCTION("""COMPUTED_VALUE"""),2.0) -> 2 | O37: =IFERROR(__xludf.DUMMYFUNCTION("""COMPUTED_VALUE"""),3.0) -> 3 | P37: =IFERROR(__xludf.DUMMYFUNCTION("""COMPUTED_VALUE"""),FALSE) -> FALSE | Q37: =IFERROR(__xludf.DUMMYFUNCTION("""COMPUTED_VALUE"""),FALSE) -> FALSE | S37: Cyproheptadine | T37: {=XLOOKUP(S37, MAPK8IP3, B3:B1000, XLOOKUP(S37, ZC4H2, H3:H1000, XLOOKUP(S37, SLC6A1, N3:N1000)))} -> 6 | U37: {=XLOOKUP(S37, MAPK8IP3, C3:C1000, XLOOKUP(S37, ZC4H2, I3:I1000, XLOOKUP(S37, SLC6A1, O3:O1000)))} -> 3 | V37: {=XLOOKUP(S37, MAPK8IP3, D3:D1000, XLOOKUP(S37, ZC4H2, J3:J1000, XLOOKUP(S37, SLC6A1, P3:P1000)))} -> FALSE
A38: =IFERROR(__xludf.DUMMYFUNCTION("""COMPUTED_VALUE"""),"Levodopa") -> Levodopa | B38: =IFERROR(__xludf.DUMMYFUNCTION("""COMPUTED_VALUE"""),5.0) -> 5 | C38: =IFERROR(__xludf.DUMMYFUNCTION("""COMPUTED_VALUE"""),3.0) -> 3 | D38: =IFERROR(__xludf.DUMMYFUNCTION("""COMPUTED_VALUE"""),TRUE) -> TRUE | E38: =IFERROR(__xludf.DUMMYFUNCTION("""COMPUTED_VALUE"""),TRUE) -> TRUE | G38: =IFERROR(__xludf.DUMMYFUNCTION("""COMPUTED_VALUE"""),"Ciclopirox") -> Ciclopirox | H38: =IFERROR(__xludf.DUMMYFUNCTION("""COMPUTED_VALUE"""),4.0) -> 4 | I38: =IFERROR(__xludf.DUMMYFUNCTION("""COMPUTED_VALUE"""),3.0) -> 3 | J38: =IFERROR(__xludf.DUMMYFUNCTION("""COMPUTED_VALUE"""),FALSE) -> FALSE | K38: =IFERROR(__xludf.DUMMYFUNCTION("""COMPUTED_VALUE"""),FALSE) -> FALSE | M38: =IFERROR(__xludf.DUMMYFUNCTION("""COMPUTED_VALUE"""),"Felbamate") -> Felbamate | N38: =IFERROR(__xludf.DUMMYFUNCTION("""COMPUTED_VALUE"""),1.0) -> 1 | O38: =IFERROR(__xludf.DUMMYFUNCTION("""COMPUTED_VALUE"""),3.0) -> 3 | P38: =IFERROR(__xludf.DUMMYFUNCTION("""COMPUTED_VALUE"""),FALSE) -> FALSE | Q38: =IFERROR(__xludf.DUMMYFUNCTION("""COMPUTED_VALUE"""),FALSE) -> FALSE | S38: Dantrolene | T38: {=XLOOKUP(S38, MAPK8IP3, B3:B1000, XLOOKUP(S38, ZC4H2, H3:H1000, XLOOKUP(S38, SLC6A1, N3:N1000)))} -> 6 | U38: {=XLOOKUP(S38, MAPK8IP3, C3:C1000, XLOOKUP(S38, ZC4H2, I3:I1000, XLOOKUP(S38, SLC6A1, O3:O1000)))} -> 3 | V38: {=XLOOKUP(S38, MAPK8IP3, D3:D1000, XLOOKUP(S38, ZC4H2, J3:J1000, XLOOKUP(S38, SLC6A1, P3:P1000)))} -> TRUE
A39: =IFERROR(__xludf.DUMMYFUNCTION("""COMPUTED_VALUE"""),"Lidocaine") -> Lidocaine | B39: =IFERROR(__xludf.DUMMYFUNCTION("""COMPUTED_VALUE"""),5.0) -> 5 | C39: =IFERROR(__xludf.DUMMYFUNCTION("""COMPUTED_VALUE"""),3.0) -> 3 | D39: =IFERROR(__xludf.DUMMYFUNCTION("""COMPUTED_VALUE"""),FALSE) -> FALSE | E39: =IFERROR(__xludf.DUMMYFUNCTION("""COMPUTED_VALUE"""),FALSE) -> FALSE | G39: =IFERROR(__xludf.DUMMYFUNCTION("""COMPUTED_VALUE"""),"Guanfacine") -> Guanfacine | H39: =IFERROR(__xludf.DUMMYFUNCTION("""COMPUTED_VALUE"""),4.0) -> 4 | I39: =IFERROR(__xludf.DUMMYFUNCTION("""COMPUTED_VALUE"""),3.0) -> 3 | J39: =IFERROR(__xludf.DUMMYFUNCTION("""COMPUTED_VALUE"""),TRUE) -> TRUE | K39: =IFERROR(__xludf.DUMMYFUNCTION("""COMPUTED_VALUE"""),FALSE) -> FALSE | M39: =IFERROR(__xludf.DUMMYFUNCTION("""COMPUTED_VALUE"""),"Flunarizine") -> Flunarizine | N39: =IFERROR(__xludf.DUMMYFUNCTION("""COMPUTED_VALUE"""),2.0) -> 2 | O39: =IFERROR(__xludf.DUMMYFUNCTION("""COMPUTED_VALUE"""),3.0) -> 3 | P39: =IFERROR(__xludf.DUMMYFUNCTION("""COMPUTED_VALUE"""),FALSE) -> FALSE | Q39: =IFERROR(__xludf.DUMMYFUNCTION("""COMPUTED_VALUE"""),FALSE) -> FALSE | S39: Daprodustat | T39: {=XLOOKUP(S39, MAPK8IP3, B3:B1000, XLOOKUP(S39, ZC4H2, H3:H1000, XLOOKUP(S39, SLC6A1, N3:N1000)))} -> -1 | U39: {=XLOOKUP(S39, MAPK8IP3, C3:C1000, XLOOKUP(S39, ZC4H2, I3:I1000, XLOOKUP(S39, SLC6A1, O3:O1000)))} -> 1 | V39: {=XLOOKUP(S39, MAPK8IP3, D3:D1000, XLOOKUP(S39, ZC4H2, J3:J1000, XLOOKUP(S39, SLC6A1, P3:P1000)))} -> TRUE
A40: =IFERROR(__xludf.DUMMYFUNCTION("""COMPUTED_VALUE"""),"Midodrine") -> Midodrine | B40: =IFERROR(__xludf.DUMMYFUNCTION("""COMPUTED_VALUE"""),5.0) -> 5 | C40: =IFERROR(__xludf.DUMMYFUNCTION("""COMPUTED_VALUE"""),3.0) -> 3 | D40: =IFERROR(__xludf.DUMMYFUNCTION("""COMPUTED_VALUE"""),FALSE) -> FALSE | E40: =IFERROR(__xludf.DUMMYFUNCTION("""COMPUTED_VALUE"""),FALSE) -> FALSE | G40: =IFERROR(__xludf.DUMMYFUNCTION("""COMPUTED_VALUE"""),"Levetiracetam") -> Levetiracetam | H40: =IFERROR(__xludf.DUMMYFUNCTION("""COMPUTED_VALUE"""),4.0) -> 4 | I40: =IFERROR(__xludf.DUMMYFUNCTION("""COMPUTED_VALUE"""),3.0) -> 3 | J40: =IFERROR(__xludf.DUMMYFUNCTION("""COMPUTED_VALUE"""),FALSE) -> FALSE | K40: =IFERROR(__xludf.DUMMYFUNCTION("""COMPUTED_VALUE"""),FALSE) -> FALSE | M40: =IFERROR(__xludf.DUMMYFUNCTION("""COMPUTED_VALUE"""),"Fluvoxamine") -> Fluvoxamine | N40: =IFERROR(__xludf.DUMMYFUNCTION("""COMPUTED_VALUE"""),6.0) -> 6 | O40: =IFERROR(__xludf.DUMMYFUNCTION("""COMPUTED_VALUE"""),3.0) -> 3 | P40: =IFERROR(__xludf.DUMMYFUNCTION("""COMPUTED_VALUE"""),TRUE) -> TRUE | Q40: =IFERROR(__xludf.DUMMYFUNCTION("""COMPUTED_VALUE"""),FALSE) -> FALSE | S40: Desflurane | T40: {=XLOOKUP(S40, MAPK8IP3, B3:B1000, XLOOKUP(S40, ZC4H2, H3:H1000, XLOOKUP(S40, SLC6A1, N3:N1000)))} -> 0 | U40: {=XLOOKUP(S40, MAPK8IP3, C3:C1000, XLOOKUP(S40, ZC4H2, I3:I1000, XLOOKUP(S40, SLC6A1, O3:O1000)))} -> 3 | V40: {=XLOOKUP(S40, MAPK8IP3, D3:D1000, XLOOKUP(S40, ZC4H2, J3:J1000, XLOOKUP(S40, SLC6A1, P3:P1000)))} -> FALSE
...

Sheet Commonality
A1: Total Count | C1: Common Drugs | D1: Score | E1: Count | G1: MAPK8IP3 Unique Drugs | H1: Score | I1: Count | K1: ZC4H2 Unique Drugs | L1: Score | M1: Count | O1: SLC6A1 Unique Drugs | P1: Score | Q1: Count
